Workbook

Sheet How to Use
B2: Robotics & AI Club: 16-Class Curriculum Hardware Guide (8 weeks, 2 classes a week)
B3: Curriculum developed by Qasim Mushtaq, MS Robotics and AI · Pak-Turk Maarif International Schools & Colleges, Chak Shahzad Campus
B5: Tabs
B6: 16-Class Plan | C6: Class-by-class plan (2 classes a week, 8 weeks) for all 4 age groups with activity code, domains, software, SDGs and main outcome. Click a code to open its kit.
B7: Little Explorers (Ages 5-7) | C7: Kit list per activity (LE-01 to LE-16). Quantities are PER GROUP unless marked Per class.
B8: Junior Makers (Ages 8-11) | C8: Kit list per activity (JM-01 to JM-16). Quantities are PER GROUP unless marked Per class.
B9: Young Innovators (Ages 12-14) | C9: Kit list per activity (YI-01 to YI-16). Quantities are PER GROUP unless marked Per class.
B10: Tech Leaders (Ages 15-17) | C10: Kit list per activity (TL-01 to TL-16). Quantities are PER GROUP unless marked Per class.
B11: Master Hardware | C11: Every component used, by category. Counts and maximum quantities are live formulas reading the four kit tabs.
B12: Software Guide | C12: All software tools used, with age suitability and which activities use them.
B14: Assumptions
B15: Group size | C15: 1 group = 2 students. Multiply 'Per group' quantities by the number of groups.
B16: Per class | C16: Shared per room (3D printer, glue gun, candle for teacher demos). Do not multiply by groups.
B17: Reusable vs consumable | C17: Reusable parts are reused every class: order enough for your largest session plus 10-20% spares. Consumables (LEDs, resistors, batteries, tape, fruit) are used up: add them across every session.
B18: Codes | C18: LE = Little Explorers (5-7), JM = Junior Makers (8-11), YI = Young Innovators (12-14), TL = Tech Leaders (15-17). Classes 17-18 are capstone projects built from existing kits.
B19: Safety | C19: Ages 5-7: all wiring pre-done by the teacher. Flame and gas tests are teacher-only. Li-ion (18650) work is supervised; use protected cells. Relays switch low-voltage loads only.

Sheet 16-Class Plan
A1: 16-Class Plan: 4 age groups x 16 classes (2 a week, 8 weeks) + optional capstone showcase after the batch
A2: Curriculum developed by Qasim Mushtaq, MS Robotics and AI
A4: Age group | B4: Phase | C4: Class (Week) | D4: Code | E4: Activity | F4: Domain | G4: Second domain | H4: Mode | I4: Primary software | J4: SDGs | K4: Main learning outcome
A5: Little Explorers (Ages 5-7) | Curious hands, big ideas
A6: Ages 5-7 | B6: Circuits & Power | C6: 1 (W1) | D6: LE-01 | E6: Light-Up Paper Circuit Card | F6: Electronics & Circuits | G6: - | H6: Hardware | I6: No software needed | J6: SDG 4, SDG 7 | K6: Science: Electricity flows only in a closed loop; Technology: Batteries have a + and a - side; Arts: Designing a personalised card
A7: Ages 5-7 | B7: Circuits & Power | C7: 2 (W1) | D7: LE-02 | E7: Push-Button Doorbell | F7: Electronics & Circuits | G7: - | H7: Hardware | I7: mBlock 5 / ArduBlock (picture blocks) | J7: SDG 4, SDG 10 | K7: Science: Pressing a button closes a circuit; Technology: Inputs and outputs; Life Skills: Designing for people with different needs
A8: Ages 5-7 | B8: Circuits & Power | C8: 3 (W2) | D8: LE-03 | E8: Lemon Battery LED Lamp | F8: Power & Energy | G8: - | H8: Hardware | I8: No software needed | J8: SDG 7, SDG 4 | K8: Science: Chemical energy can become electrical energy; Maths: Counting and comparing results; Engineering: Connecting cells in series
A9: Ages 5-7 | B9: Circuits & Power | C9: 4 (W2) | D9: LE-04 | E9: Traffic Light Controller | F9: Programming & Logic | G9: - | H9: Hardware | I9: mBlock 5 / ArduBlock (picture blocks) | J9: SDG 11, SDG 4 | K9: Computing: Sequences: instructions run in order; Maths: Time in seconds; Life Skills: Road safety
A10: Ages 5-7 | B10: Sensing the World | C10: 5 (W3) | D10: LE-05 | E10: Automatic Night Lamp | F10: Sensors & Environment | G10: - | H10: Hardware | I10: mBlock 5 / ArduBlock (picture blocks) | J10: SDG 7, SDG 11 | K10: Science: Light and darkness can be measured; Computing: If-then decisions; Life Skills: Saving energy
A11: Ages 5-7 | B11: Sensing the World | C11: 6 (W3) | D11: LE-06 | E11: Hot & Cold Temperature Indicator | F11: Sensors & Environment | G11: - | H11: Hardware | I11: mBlock 5 / ArduBlock (picture blocks) | J11: SDG 3, SDG 13 | K11: Science: Hot and cold can be measured; Maths: Comparing bigger and smaller numbers; Computing: Thresholds in decisions
A12: Ages 5-7 | B12: Sensing the World | C12: 7 (W4) | D12: LE-07 | E12: Plant Water Alarm | F12: Sensors & Environment | G12: - | H12: Hardware | I12: mBlock 5 / ArduBlock (picture blocks) | J12: SDG 2, SDG 15 | K12: Science: Plants need water to live; Technology: Sensors in farming; Life Skills: Caring for living things
A13: Ages 5-7 | B13: Sensing the World | C13: 8 (W4) | D13: LE-08 | E13: Motion Detector Room Alarm | F13: Security & Safety | G13: - | H13: Hardware | I13: mBlock 5 / ArduBlock (picture blocks) | J13: SDG 11, SDG 16 | K13: Science: Our bodies give off heat; Technology: Motion sensors in security; Life Skills: Keeping homes safe
A14: Ages 5-7 | B14: Move & Communicate | C14: 9 (W5) | D14: LE-09 | E14: Waving Robot Arm | F14: Robotics & Actuation | G14: - | H14: Hardware | I14: mBlock 5 / ArduBlock (picture blocks) | J14: SDG 9, SDG 4 | K14: Engineering: Motors create movement; Maths: Turning and angles; Arts: Designing a robot character
A15: Ages 5-7 | B15: Move & Communicate | C15: 10 (W5) | D15: LE-10 | E15: Automatic Railway Crossing Gate | F15: Robotics & Actuation | G15: - | H15: Hardware | I15: mBlock 5 / ArduBlock (picture blocks) | J15: SDG 9, SDG 11 | K15: Engineering: Sensors, decisions and motors working together; Science: Echoes measure distance; Life Skills: Railway safety
A16: Ages 5-7 | B16: Move & Communicate | C16: 11 (W6) | D16: LE-11 | E16: Vibrating Brush Robot | F16: Mechanical Design | G16: - | H16: Hardware | I16: No software needed | J16: SDG 9, SDG 4 | K16: Engineering: Balance and weight change movement; Science: Vibration is a kind of motion; Life Skills: Improving after a test
A17: Ages 5-7 | B17: Move & Communicate | C17: 12 (W6) | D17: LE-12 | E17: Morse Code Light Messenger | F17: IoT & Communication | G17: - | H17: Hardware | I17: mBlock 5 / ArduBlock (picture blocks) | J17: SDG 9, SDG 17 | K17: Computing: Information can be sent as patterns (codes); Science: Light and sound carry messages; Life Skills: Listening and taking turns
... A23: Ages 5-7 | B23: Capstone (optional, after the batch) | C23: Extra B | D23: - | E23: Project-based learning: plan, build, test, showcase | F23: All domains | G23: - | H23: Hardware + Software | I23: Mixed | J23: - | K23: Suggested: Light-up invention for my bedroom; Smart plant pot helper; Makey Makey musical instrument; Talking robot face with lights and sounds
A25: Junior Makers (Ages 8-11) | From circuits to coded robots
A26: Ages 8-11 | B26: Circuits, Code & Sensing | C26: 1 (W1) | D26: JM-01 | E26: Series & Parallel Circuit Lab | F26: Electronics & Circuits | G26: - | H26: Hardware + Software | I26: PhET Circuit Construction Kit | J26: SDG 4, SDG 7 | K26: Science: Current, voltage and circuit paths; Technology: Using a multimeter safely; Maths: Recording and comparing measurements
A27: Ages 8-11 | B27: Circuits, Code & Sensing | C27: 2 (W1) | D27: JM-02 | E27: Two-Player Reaction Timer with Scoreboard | F27: Programming & Logic | G27: - | H27: Hardware | I27: ArduinoBlocks | J27: SDG 3, SDG 4 | K27: Computing: Variables, random numbers and timing; Maths: Milliseconds and comparing times; Life Skills: Fair play
A28: Ages 8-11 | B28: Circuits, Code & Sensing | C28: 3 (W2) | D28: JM-03 | E28: Mini Weather Station with OLED Display | F28: Sensors & Environment | G28: - | H28: Hardware | I28: ArduinoBlocks | J28: SDG 13, SDG 11 | K28: Science: Weather: temperature, humidity and light; Computing: Reading multiple sensors; Maths: Tables and comparing data
A29: Ages 8-11 | B29: Circuits, Code & Sensing | C29: 4 (W2) | D29: JM-04 | E29: Smart Dustbin with Fill-Level Indicator | F29: Robotics & Actuation | G29: - | H29: Hardware | I29: ArduinoBlocks | J29: SDG 11, SDG 12, SDG 3 | K29: Engineering: Combining two sensors and a motor; Computing: Conditions with ranges; Life Skills: Hygiene and clean cities
A30: Ages 8-11 | B30: Smart Home & Energy | C30: 5 (W3) | D30: JM-05 | E30: Rain-Sensing Automatic Window | F30: Sensors & Environment | G30: Mechanical Design | H30: Hardware | I30: ArduinoBlocks | J30: SDG 11, SDG 13 | K30: Science: Water conducts electricity; Engineering: Hinges and mechanisms; Computing: Sensor-triggered actions
A31: Ages 8-11 | B31: Smart Home & Energy | C31: 6 (W3) | D31: JM-06 | E31: Fire & Gas Safety Alarm Panel | F31: Security & Safety | G31: Sensors & Environment | H31: Hardware | I31: ArduinoBlocks | J31: SDG 3, SDG 11 | K31: Science: Fire, smoke and gases; Technology: Safety sensors in buildings; Life Skills: Emergency response
A32: Ages 8-11 | B32: Smart Home & Energy | C32: 7 (W4) | D32: JM-07 | E32: Temperature-Controlled Smart Fan | F32: Robotics & Actuation | G32: - | H32: Hardware | I32: ArduinoBlocks | J32: SDG 7, SDG 13 | K32: Engineering: Motor drivers and speed control; Science: Heat and cooling; Computing: Mapping one range to another
A33: Ages 8-11 | B33: Smart Home & Energy | C33: 8 (W4) | D33: JM-08 | E33: Sun-Tracking Solar Panel | F33: Power & Energy | G33: Sensors & Environment | H33: Hardware | I33: ArduinoBlocks | J33: SDG 7, SDG 13 | K33: Science: The sun as an energy source; Engineering: Feedback: sense, compare, move; Maths: Comparing measurements
A34: Ages 8-11 | B34: Security, Design & Robots | C34: 9 (W5) | D34: JM-09 | E34: Home Burglar Alarm with Secret Code | F34: Security & Safety | G34: - | H34: Hardware | I34: ArduinoBlocks | J34: SDG 11, SDG 16 | K34: Computing: Sequences, passwords and states; Technology: Home security systems; Life Skills: Keeping codes private
A35: Ages 8-11 | B35: Security, Design & Robots | C35: 10 (W5) | D35: JM-10 | E35: 3D-Designed Name Badge & Sensor Mount | F35: Mechanical Design | G35: - | H35: Software | I35: Tinkercad 3D | J35: SDG 9 | K35: Engineering: Designing parts to measured sizes; Maths: Millimetres and 3D shapes; Arts: Product design
A36: Ages 8-11 | B36: Security, Design & Robots | C36: 11 (W6) | D36: JM-11 | E36: Line Following Robot | F36: Robotics & Actuation | G36: - | H36: Hardware | I36: ArduinoBlocks | J36: SDG 9 | K36: Engineering: Robot chassis, motors and sensors; Computing: Decisions inside a loop; Technology: Robots in industry
A37: Ages 8-11 | B37: Security, Design & Robots | C37: 12 (W6) | D37: JM-12 | E37: Phone-Controlled RGB Mood Lamp | F37: IoT & Communication | G37: App, Web & Game Development | H37: Hardware + Software | I37: ArduinoBlocks + MIT App Inventor | J37: SDG 7, SDG 9 | K37: Computing: Wireless messages between devices; Science: Colour mixing with light; Technology: Smart homes
... A43: Ages 8-11 | B43: Capstone (optional, after the batch) | C43: Extra B | D43: - | E43: Project-based learning: plan, build, test, showcase | F43: All domains | G43: - | H43: Hardware + Software | I43: Mixed | J43: - | K43: Suggested: Automatic pet feeder with a timer; Smart study lamp with posture reminder; Obstacle avoiding delivery car; Classroom noise-level meter
A45: Young Innovators (Ages 12-14) | Real code, real electronics, real problems
A46: Ages 12-14 | B46: Electronics & Mechanisms | C46: 1 (W1) | D46: YI-01 | E46: 555 Timer Alarm Siren Circuit | F46: Electronics & Circuits | G46: - | H46: Hardware | I46: Falstad Circuit Simulator | J46: SDG 4, SDG 9 | K46: Science: Capacitors, resistance and charging time; Engineering: Integrated circuits without code; Maths: Frequency and period
A47: Ages 12-14 | B47: Electronics & Mechanisms | C47: 2 (W1) | D47: YI-02 | E47: Heart Rate Monitoring System | F47: Sensors & Environment | G47: - | H47: Hardware | I47: Arduino IDE 2 | J47: SDG 3 | K47: Science: The heart and circulation; Computing: Signal thresholds, timing and averages; Life Skills: Health data privacy
A48: Ages 12-14 | B48: Electronics & Mechanisms | C48: 3 (W2) | D48: YI-03 | E48: Smart Classroom Energy Saver | F48: Power & Energy | G48: Sensors & Environment | H48: Hardware | I48: Arduino IDE 2 | J48: SDG 7, SDG 13, SDG 11 | K48: Engineering: Relays and automation; Computing: Combined conditions (AND/OR) and timers; Maths: Estimating energy savings
A49: Ages 12-14 | B49: Electronics & Mechanisms | C49: 4 (W2) | D49: YI-04 | E49: Stepper Motor Drawing Plotter | F49: Mechanical Design | G49: Programming & Logic | H49: Hardware | I49: Arduino IDE 2 | J49: SDG 9 | K49: Engineering: Stepper motors and mechanisms; Maths: Coordinates and ratios; Computing: Functions for reusable moves
A50: Ages 12-14 | B50: Robots & Security | C50: 5 (W3) | D50: YI-05 | E50: Obstacle Avoiding Robot with Scanning Sonar | F50: Robotics & Actuation | G50: - | H50: Hardware | I50: Arduino IDE 2 | J50: SDG 9, SDG 11 | K50: Engineering: Autonomous navigation; Computing: Functions and comparisons; Technology: How self-driving cars sense
A51: Ages 12-14 | B51: Robots & Security | C51: 6 (W3) | D51: YI-06 | E51: Bluetooth Robot Car with Phone App | F51: IoT & Communication | G51: App, Web & Game Development | H51: Hardware + Software | I51: Arduino IDE 2 + MIT App Inventor | J51: SDG 9 | K51: Computing: Serial communication and app design; Engineering: Wireless control systems; Arts: User interface design
A52: Ages 12-14 | B52: Robots & Security | C52: 7 (W4) | D52: YI-07 | E52: Gesture-Controlled Robot Arm | F52: Robotics & Actuation | G52: - | H52: Hardware | I52: Arduino IDE 2 | J52: SDG 9, SDG 3 | K52: Engineering: Robot arms and degrees of freedom; Maths: Angles and mapping ranges; Computing: Smoothing noisy sensor data
A53: Ages 12-14 | B53: Robots & Security | C53: 8 (W4) | D53: YI-08 | E53: RFID Smart Door Lock with Access Log | F53: Security & Safety | G53: - | H53: Hardware | I53: Arduino IDE 2 | J53: SDG 9, SDG 16 | K53: Computing: Arrays, comparisons and logs; Technology: RFID in everyday life; Life Skills: Privacy and access rights
...

Sheet Little Explorers 5-7
A1: Little Explorers (Ages 5-7): kit per activity
A2: Quantities per group of 2 students. 'Per class' = shared, do not multiply.
A4: Code | B4: Category | C4: Component | D4: Qty | E4: Basis | F4: Type | G4: Notes
A5: LE-01 | B5: Class 1 (Week 1) · Light-Up Paper Circuit Card
A6: LE-01 | B6: Domain: Electronics & Circuits | Mode: Hardware | Software: No software needed (also: PhET Circuit Construction Kit (teacher demo)) SDGs: 4 Quality Education, 7 Clean Energy
A7: LE-01 | B7: Displays & Output | C7: LED 5 mm (assorted) | D7: 2 | E7: Per group | F7: Consumable
A8: LE-01 | B8: Power | C8: Coin cell CR2032 | D8: 1 | E8: Per group | F8: Consumable
A9: LE-01 | B9: Wiring & Prototyping | C9: Copper tape | D9: 1 | E9: Per group | F9: Consumable | G9: 30 cm per group
A10: LE-01 | B10: Craft & Stationery | C10: Card / chart paper | D10: 2 | E10: Per group | F10: Consumable
A11: LE-01 | B11: Craft & Stationery | C11: Markers | D11: 1 | E11: Per group | F11: Consumable
A12: LE-01 | B12: Craft & Stationery | C12: Tape (paper + double-sided) | D12: 1 | E12: Per class | F12: Consumable
A14: LE-02 | B14: Class 2 (Week 1) · Push-Button Doorbell
A15: LE-02 | B15: Domain: Electronics & Circuits | Mode: Hardware | Software: mBlock 5 / ArduBlock (picture blocks) (also: Tinkercad Circuits (teacher demo)) SDGs: 4 Quality Education, 10 Reduced Inequalities
A16: LE-02 | B16: Microcontrollers & Dev Boards | C16: Arduino Uno + USB cable | D16: 1 | E16: Per group | F16: Reusable | G16: Pre-wired by teacher
A17: LE-02 | B17: Actuators & Motor Drivers | C17: Buzzer | D17: 1 | E17: Per group | F17: Reusable
A18: LE-02 | B18: Displays & Output | C18: LED 5 mm (assorted) | D18: 1 | E18: Per group | F18: Consumable
A19: LE-02 | B19: Passive Components & ICs | C19: Push button | D19: 1 | E19: Per group | F19: Reusable
A20: LE-02 | B20: Passive Components & ICs | C20: Resistor 220 ohm | D20: 1 | E20: Per group | F20: Consumable
A21: LE-02 | B21: Passive Components & ICs | C21: Resistor 10k ohm | D21: 1 | E21: Per group | F21: Consumable
A22: LE-02 | B22: Wiring & Prototyping | C22: Breadboard (half size) | D22: 1 | E22: Per group | F22: Reusable
A23: LE-02 | B23: Wiring & Prototyping | C23: Jumper wires M-M | D23: 6 | E23: Per group | F23: Reusable
A24: LE-02 | B24: Computers & Equipment | C24: Laptop | D24: 1 | E24: Per group | F24: Reusable
A26: LE-03 | B26: Class 3 (Week 2) · Lemon Battery LED Lamp
A27: LE-03 | B27: Domain: Power & Energy | Mode: Hardware | Software: No software needed SDGs: 7 Clean Energy, 4 Quality Education
A28: LE-03 | B28: Displays & Output | C28: LED 5 mm (assorted) | D28: 1 | E28: Per group | F28: Consumable | G28: Red works best
A29: LE-03 | B29: Wiring & Prototyping | C29: Alligator clip leads | D29: 5 | E29: Per group | F29: Reusable
A30: LE-03 | B30: Science Consumables | C30: Lemons | D30: 4 | E30: Per group | F30: Consumable
A31: LE-03 | B31: Science Consumables | C31: Galvanized nails | D31: 4 | E31: Per group | F31: Consumable
A32: LE-03 | B32: Science Consumables | C32: Copper coins | D32: 4 | E32: Per group | F32: Reusable
A34: LE-04 | B34: Class 4 (Week 2) · Traffic Light Controller
A35: LE-04 | B35: Domain: Programming & Logic | Mode: Hardware | Software: mBlock 5 / ArduBlock (picture blocks) (also: Tinkercad Circuits (teacher demo)) SDGs: 11 Sustainable Cities, 4 Quality Education
A36: LE-04 | B36: Microcontrollers & Dev Boards | C36: Arduino Uno + USB cable | D36: 1 | E36: Per group | F36: Reusable | G36: Pre-wired by teacher
A37: LE-04 | B37: Actuators & Motor Drivers | C37: Buzzer | D37: 1 | E37: Per group | F37: Reusable
A38: LE-04 | B38: Displays & Output | C38: LED 5 mm (assorted) | D38: 3 | E38: Per group | F38: Consumable | G38: Red, yellow, green
A39: LE-04 | B39: Passive Components & ICs | C39: Resistor 220 ohm | D39: 3 | E39: Per group | F39: Consumable
A40: LE-04 | B40: Wiring & Prototyping | C40: Breadboard (half size) | D40: 1 | E40: Per group | F40: Reusable
A41: LE-04 | B41: Wiring & Prototyping | C41: Jumper wires M-M | D41: 8 | E41: Per group | F41: Reusable
A42: LE-04 | B42: Computers & Equipment | C42: Laptop | D42: 1 | E42: Per group | F42: Reusable
A44: LE-05 | B44: Class 5 (Week 3) · Automatic Night Lamp
A45: LE-05 | B45: Domain: Sensors & Environment | Mode: Hardware | Software: mBlock 5 / ArduBlock (picture blocks) SDGs: 7 Clean Energy, 11 Sustainable Cities
...

Sheet Junior Makers 8-11
A1: Junior Makers (Ages 8-11): kit per activity
A2: Quantities per group of 2 students. 'Per class' = shared, do not multiply.
A4: Code | B4: Category | C4: Component | D4: Qty | E4: Basis | F4: Type | G4: Notes
A5: JM-01 | B5: Class 1 (Week 1) · Series & Parallel Circuit Lab
A6: JM-01 | B6: Domain: Electronics & Circuits | Mode: Hardware + Software | Software: PhET Circuit Construction Kit (also: Tinkercad Circuits) SDGs: 4 Quality Education, 7 Clean Energy
A7: JM-01 | B7: Displays & Output | C7: LED 5 mm (assorted) | D7: 4 | E7: Per group | F7: Consumable
A8: JM-01 | B8: Passive Components & ICs | C8: Resistor 220 ohm | D8: 4 | E8: Per group | F8: Consumable
A9: JM-01 | B9: Passive Components & ICs | C9: Slide switch | D9: 2 | E9: Per group | F9: Reusable
A10: JM-01 | B10: Power | C10: 9V battery + snap | D10: 1 | E10: Per group | F10: Consumable
A11: JM-01 | B11: Wiring & Prototyping | C11: Breadboard (half size) | D11: 1 | E11: Per group | F11: Reusable
A12: JM-01 | B12: Wiring & Prototyping | C12: Jumper wires M-M | D12: 10 | E12: Per group | F12: Reusable
A13: JM-01 | B13: Computers & Equipment | C13: Digital multimeter | D13: 1 | E13: Per group | F13: Reusable
A14: JM-01 | B14: Computers & Equipment | C14: Laptop | D14: 1 | E14: Per group | F14: Reusable
A16: JM-02 | B16: Class 2 (Week 1) · Two-Player Reaction Timer with Scoreboard
A17: JM-02 | B17: Domain: Programming & Logic | Mode: Hardware | Software: ArduinoBlocks (also: Wokwi; Arduino IDE 2) SDGs: 3 Good Health, 4 Quality Education
A18: JM-02 | B18: Microcontrollers & Dev Boards | C18: Arduino Uno + USB cable | D18: 1 | E18: Per group | F18: Reusable
A19: JM-02 | B19: Actuators & Motor Drivers | C19: Buzzer | D19: 1 | E19: Per group | F19: Reusable
A20: JM-02 | B20: Displays & Output | C20: LED 5 mm (assorted) | D20: 2 | E20: Per group | F20: Consumable
A21: JM-02 | B21: Displays & Output | C21: OLED 0.96 in I2C | D21: 1 | E21: Per group | F21: Reusable
A22: JM-02 | B22: Passive Components & ICs | C22: Push button | D22: 2 | E22: Per group | F22: Reusable
A23: JM-02 | B23: Passive Components & ICs | C23: Resistor 220 ohm | D23: 2 | E23: Per group | F23: Consumable
A24: JM-02 | B24: Passive Components & ICs | C24: Resistor 10k ohm | D24: 2 | E24: Per group | F24: Consumable
A25: JM-02 | B25: Wiring & Prototyping | C25: Breadboard (half size) | D25: 1 | E25: Per group | F25: Reusable
A26: JM-02 | B26: Wiring & Prototyping | C26: Jumper wires M-M | D26: 14 | E26: Per group | F26: Reusable
A27: JM-02 | B27: Wiring & Prototyping | C27: Jumper wires M-F | D27: 4 | E27: Per group | F27: Reusable
A28: JM-02 | B28: Computers & Equipment | C28: Laptop | D28: 1 | E28: Per group | F28: Reusable
A30: JM-03 | B30: Class 3 (Week 2) · Mini Weather Station with OLED Display
A31: JM-03 | B31: Domain: Sensors & Environment | Mode: Hardware | Software: ArduinoBlocks (also: Wokwi (DHT22 + OLED)) SDGs: 13 Climate Action, 11 Sustainable Cities
A32: JM-03 | B32: Microcontrollers & Dev Boards | C32: Arduino Uno + USB cable | D32: 1 | E32: Per group | F32: Reusable
A33: JM-03 | B33: Sensors | C33: DHT22 sensor | D33: 1 | E33: Per group | F33: Reusable
A34: JM-03 | B34: Sensors | C34: LDR module | D34: 1 | E34: Per group | F34: Reusable
A35: JM-03 | B35: Displays & Output | C35: OLED 0.96 in I2C | D35: 1 | E35: Per group | F35: Reusable
A36: JM-03 | B36: Passive Components & ICs | C36: Resistor 10k ohm | D36: 1 | E36: Per group | F36: Consumable
A37: JM-03 | B37: Wiring & Prototyping | C37: Breadboard (half size) | D37: 1 | E37: Per group | F37: Reusable
A38: JM-03 | B38: Wiring & Prototyping | C38: Jumper wires M-M | D38: 10 | E38: Per group | F38: Reusable
A39: JM-03 | B39: Wiring & Prototyping | C39: Jumper wires M-F | D39: 6 | E39: Per group | F39: Reusable
A40: JM-03 | B40: Computers & Equipment | C40: Laptop | D40: 1 | E40: Per group | F40: Reusable
A42: JM-04 | B42: Class 4 (Week 2) · Smart Dustbin with Fill-Level Indicator
A43: JM-04 | B43: Domain: Robotics & Actuation | Mode: Hardware | Software: ArduinoBlocks (also: Tinkercad Circuits; Wokwi) SDGs: 11 Sustainable Cities, 12 Responsible Consumption, 3 Good Health
A44: JM-04 | B44: Microcontrollers & Dev Boards | C44: Arduino Uno + USB cable | D44: 1 | E44: Per group | F44: Reusable
...

Sheet Young Innovators 12-14
A1: Young Innovators (Ages 12-14): kit per activity
A2: Quantities per group of 2 students. 'Per class' = shared, do not multiply.
A4: Code | B4: Category | C4: Component | D4: Qty | E4: Basis | F4: Type | G4: Notes
A5: YI-01 | B5: Class 1 (Week 1) · 555 Timer Alarm Siren Circuit
A6: YI-01 | B6: Domain: Electronics & Circuits | Mode: Hardware | Software: Falstad Circuit Simulator (also: Tinkercad Circuits (has a 555)) SDGs: 4 Quality Education, 9 Industry & Innovation
A7: YI-01 | B7: Actuators & Motor Drivers | C7: Buzzer | D7: 1 | E7: Per group | F7: Reusable
A8: YI-01 | B8: Displays & Output | C8: LED 5 mm (assorted) | D8: 1 | E8: Per group | F8: Consumable
A9: YI-01 | B9: Passive Components & ICs | C9: 555 timer IC | D9: 1 | E9: Per group | F9: Consumable
A10: YI-01 | B10: Passive Components & ICs | C10: Capacitor 10 uF | D10: 1 | E10: Per group | F10: Consumable
A11: YI-01 | B11: Passive Components & ICs | C11: Capacitor 10 nF | D11: 1 | E11: Per group | F11: Consumable
A12: YI-01 | B12: Passive Components & ICs | C12: Capacitor 100 uF | D12: 1 | E12: Per group | F12: Consumable
A13: YI-01 | B13: Passive Components & ICs | C13: Resistor 1k ohm | D13: 2 | E13: Per group | F13: Consumable
A14: YI-01 | B14: Passive Components & ICs | C14: Resistor 10k ohm | D14: 1 | E14: Per group | F14: Consumable
A15: YI-01 | B15: Passive Components & ICs | C15: Resistor 220 ohm | D15: 1 | E15: Per group | F15: Consumable
A16: YI-01 | B16: Passive Components & ICs | C16: Potentiometer 10k | D16: 1 | E16: Per group | F16: Reusable
A17: YI-01 | B17: Power | C17: 9V battery + snap | D17: 1 | E17: Per group | F17: Consumable
A18: YI-01 | B18: Wiring & Prototyping | C18: Breadboard (half size) | D18: 1 | E18: Per group | F18: Reusable
... A20: YI-01 | B20: Computers & Equipment | C20: Digital multimeter | D20: 1 | E20: Per group | F20: Reusable
A22: YI-02 | B22: Class 2 (Week 1) · Heart Rate Monitoring System
A23: YI-02 | B23: Domain: Sensors & Environment | Mode: Hardware | Software: Arduino IDE 2 (also: Wokwi (OLED practice)) SDGs: 3 Good Health
A24: YI-02 | B24: Microcontrollers & Dev Boards | C24: Arduino Uno + USB cable | D24: 1 | E24: Per group | F24: Reusable
A25: YI-02 | B25: Sensors | C25: Pulse sensor | D25: 1 | E25: Per group | F25: Reusable
A26: YI-02 | B26: Actuators & Motor Drivers | C26: Buzzer | D26: 1 | E26: Per group | F26: Reusable
A27: YI-02 | B27: Displays & Output | C27: OLED 0.96 in I2C | D27: 1 | E27: Per group | F27: Reusable
A28: YI-02 | B28: Displays & Output | C28: LED 5 mm (assorted) | D28: 1 | E28: Per group | F28: Consumable
A29: YI-02 | B29: Passive Components & ICs | C29: Resistor 220 ohm | D29: 1 | E29: Per group | F29: Consumable
A30: YI-02 | B30: Wiring & Prototyping | C30: Breadboard (half size) | D30: 1 | E30: Per group | F30: Reusable
A31: YI-02 | B31: Wiring & Prototyping | C31: Jumper wires M-M | D31: 10 | E31: Per group | F31: Reusable
A32: YI-02 | B32: Wiring & Prototyping | C32: Jumper wires M-F | D32: 6 | E32: Per group | F32: Reusable
A33: YI-02 | B33: Computers & Equipment | C33: Laptop | D33: 1 | E33: Per group | F33: Reusable
A35: YI-03 | B35: Class 3 (Week 2) · Smart Classroom Energy Saver
A36: YI-03 | B36: Domain: Power & Energy + Sensors & Environment | Mode: Hardware | Software: Arduino IDE 2 (also: Wokwi; Tinkercad Circuits) SDGs: 7 Clean Energy, 13 Climate Action, 11 Sustainable Cities
A37: YI-03 | B37: Microcontrollers & Dev Boards | C37: Arduino Uno + USB cable | D37: 1 | E37: Per group | F37: Reusable
A38: YI-03 | B38: Sensors | C38: PIR motion sensor | D38: 1 | E38: Per group | F38: Reusable
A39: YI-03 | B39: Sensors | C39: LDR module | D39: 1 | E39: Per group | F39: Reusable
A40: YI-03 | B40: Actuators & Motor Drivers | C40: Relay module (1-channel) | D40: 1 | E40: Per group | F40: Reusable
A41: YI-03 | B41: Displays & Output | C41: Low-voltage LED lamp (5 V) | D41: 1 | E41: Per group | F41: Reusable
A42: YI-03 | B42: Displays & Output | C42: OLED 0.96 in I2C | D42: 1 | E42: Per group | F42: Reusable
A43: YI-03 | B43: Wiring & Prototyping | C43: Breadboard (half size) | D43: 1 | E43: Per group | F43: Reusable
A44: YI-03 | B44: Wiring & Prototyping | C44: Jumper wires M-M | D44: 10 | E44: Per group | F44: Reusable
...

Sheet Tech Leaders 15-17
A1: Tech Leaders (Ages 15-17): kit per activity
A2: Quantities per group of 2 students. 'Per class' = shared, do not multiply.
A4: Code | B4: Category | C4: Component | D4: Qty | E4: Basis | F4: Type | G4: Notes
A5: TL-01 | B5: Class 1 (Week 1) · Solar-Powered Off-Grid Weather Node
A6: TL-01 | B6: Domain: Power & Energy + Electronics & Circuits | Mode: Hardware | Software: Arduino IDE 2 (ESP32) (also: Arduino Cloud) SDGs: 7 Clean Energy, 13 Climate Action
A7: TL-01 | B7: Microcontrollers & Dev Boards | C7: ESP32 Dev Board + USB cable | D7: 1 | E7: Per group | F7: Reusable
A8: TL-01 | B8: Sensors | C8: DHT22 sensor | D8: 1 | E8: Per group | F8: Reusable
A9: TL-01 | B9: Passive Components & ICs | C9: Resistor 10k ohm | D9: 2 | E9: Per group | F9: Consumable | G9: Voltage divider
A10: TL-01 | B10: Power | C10: Small solar panel | D10: 1 | E10: Per group | F10: Reusable
A11: TL-01 | B11: Power | C11: TP4056 charger module | D11: 1 | E11: Per group | F11: Reusable
A12: TL-01 | B12: Power | C12: 18650 cell + holder | D12: 1 | E12: Per group | F12: Reusable
A13: TL-01 | B13: Wiring & Prototyping | C13: Breadboard (half size) | D13: 1 | E13: Per group | F13: Reusable
A14: TL-01 | B14: Wiring & Prototyping | C14: Jumper wires M-M | D14: 10 | E14: Per group | F14: Reusable
A15: TL-01 | B15: Wiring & Prototyping | C15: Jumper wires M-F | D15: 4 | E15: Per group | F15: Reusable
A16: TL-01 | B16: Computers & Equipment | C16: Digital multimeter | D16: 1 | E16: Per group | F16: Reusable
A17: TL-01 | B17: Computers & Equipment | C17: Laptop | D17: 1 | E17: Per group | F17: Reusable
A19: TL-02 | B19: Class 2 (Week 1) · Autonomous Maze Solving Robot
A20: TL-02 | B20: Domain: Robotics & Actuation + Programming & Logic | Mode: Hardware | Software: Arduino IDE 2 SDGs: 9 Industry & Innovation, 11 Sustainable Cities
A21: TL-02 | B21: Microcontrollers & Dev Boards | C21: Arduino Uno + USB cable | D21: 1 | E21: Per group | F21: Reusable
A22: TL-02 | B22: Robot Platforms & Kits | C22: 2WD robot chassis kit | D22: 1 | E22: Per group | F22: Reusable
A23: TL-02 | B23: Sensors | C23: Ultrasonic sensor HC-SR04 | D23: 3 | E23: Per group | F23: Reusable
A24: TL-02 | B24: Actuators & Motor Drivers | C24: L298N motor driver | D24: 1 | E24: Per group | F24: Reusable
A25: TL-02 | B25: Power | C25: 4xAA battery pack | D25: 1 | E25: Per group | F25: Consumable
A26: TL-02 | B26: Wiring & Prototyping | C26: Jumper wires M-F | D26: 14 | E26: Per group | F26: Reusable
A27: TL-02 | B27: Wiring & Prototyping | C27: Jumper wires M-M | D27: 10 | E27: Per group | F27: Reusable
A28: TL-02 | B28: Computers & Equipment | C28: Screwdriver set | D28: 1 | E28: Per group | F28: Reusable
A29: TL-02 | B29: Computers & Equipment | C29: Laptop | D29: 1 | E29: Per group | F29: Reusable
A30: TL-02 | B30: Craft & Stationery | C30: Cardboard sheet | D30: 4 | E30: Per class | F30: Consumable | G30: Maze walls
A32: TL-03 | B32: Class 3 (Week 2) · Pick-and-Place Robotic Arm with Record & Replay
A33: TL-03 | B33: Domain: Mechanical Design | Mode: Hardware | Software: Arduino IDE 2 (also: Wokwi (servos + pots)) SDGs: 9 Industry & Innovation
A34: TL-03 | B34: Microcontrollers & Dev Boards | C34: Arduino Uno + USB cable | D34: 1 | E34: Per group | F34: Reusable
A35: TL-03 | B35: Actuators & Motor Drivers | C35: Servo MG995 | D35: 2 | E35: Per group | F35: Reusable | G35: Base and shoulder
A36: TL-03 | B36: Actuators & Motor Drivers | C36: Servo SG90 | D36: 2 | E36: Per group | F36: Reusable | G36: Wrist and gripper
A37: TL-03 | B37: Passive Components & ICs | C37: Potentiometer 10k | D37: 4 | E37: Per group | F37: Reusable
A38: TL-03 | B38: Passive Components & ICs | C38: Push button | D38: 2 | E38: Per group | F38: Reusable
A39: TL-03 | B39: Passive Components & ICs | C39: Resistor 10k ohm | D39: 2 | E39: Per group | F39: Consumable
A40: TL-03 | B40: Power | C40: LM2596 buck converter | D40: 1 | E40: Per group | F40: Reusable | G40: Servo supply
A41: TL-03 | B41: Power | C41: 4xAA battery pack | D41: 1 | E41: Per group | F41: Consumable
A42: TL-03 | B42: Wiring & Prototyping | C42: Breadboard (half size) | D42: 1 | E42: Per group | F42: Reusable
A43: TL-03 | B43: Wiring & Prototyping | C43: Jumper wires M-M | D43: 16 | E43: Per group | F43: Reusable
...

Sheet Master Hardware
A1: Master Hardware List (all 64 activities)
A2: Columns F-L are live formulas. 'Max qty per group' is what one reusable kit must contain; multiply by groups running at the same time.
A4: # | B4: Category | C4: Component | D4: Recommended spec | E4: Type | F4: Activities using it | G4: LE | H4: JM | I4: YI | J4: TL | K4: Max qty per group (single activity) | L4: Max qty per class | M4: Activity codes | N4: Buying note
B5: Microcontrollers & Dev Boards (3 items)
A6: 1 | B6: Microcontrollers & Dev Boards | C6: Arduino Uno + USB cable | D6: Arduino Uno R3 (CH340 clone fine) + USB-B cable | E6: Reusable | F6: =COUNTIF('Little Explorers 5-7'!$C:$C,$C6)+COUNTIF('Junior Makers 8-11'!$C:$C,$C6)+COUNTIF('Young Innovators 12-14'!$C:$C,$C6)+COUNTIF('Tech Leaders 15-17'!$C:$C,$C6) -> 34 | G6: =COUNTIF('Little Explorers 5-7'!$C:$C,$C6) -> 9 | H6: =COUNTIF('Junior Makers 8-11'!$C:$C,$C6) -> 12 | I6: =COUNTIF('Young Innovators 12-14'!$C:$C,$C6) -> 9 | J6: =COUNTIF('Tech Leaders 15-17'!$C:$C,$C6) -> 4 | K6: =MAX(_xlfn.MAXIFS('Little Explorers 5-7'!$D:$D,'Little Explorers 5-7'!$C:$C,$C6,'Little Explorers 5-7'!$E:$E,"Per group"),_xlfn.MAXIFS('Junior Makers 8-11'!$D:$D,'Junior Makers 8-11'!$C:$C,$C6,'Junior Makers 8-11'!$E:$E,"Per group"),_xlfn.MAXIFS('Young Innovators 12-14'!$D:$D,'Young Innovators 12-14'!$C:$C,$C6,'Young Innovators 12-14'!$E:$E,"Per group"),_xlfn.MAXIFS('Tech Leaders 15-17'!$D:$D,'Tech Leaders 15-17'!$C:$C,$C6,'Tech Leaders 15-17'!$E:$E,"Per group")) -> 2 | L6: =MAX(_xlfn.MAXIFS('Little Explorers 5-7'!$D:$D,'Little Explorers 5-7'!$C:$C,$C6,'Little Explorers 5-7'!$E:$E,"Per class"),_xlfn.MAXIFS('Junior Makers 8-11'!$D:$D,'Junior Makers 8-11'!$C:$C,$C6,'Junior Makers 8-11'!$E:$E,"Per class"),_xlfn.MAXIFS('Young Innovators 12-14'!$D:$D,'Young Innovators 12-14'!$C:$C,$C6,'Young Innovators 12-14'!$E:$E,"Per class"),_xlfn.MAXIFS('Tech Leaders 15-17'!$D:$D,'Tech Leaders 15-17'!$C:$C,$C6,'Tech Leaders 15-17'!$E:$E,"Per class")) -> 0 | M6: JM-02, JM-03, JM-04, JM-05, JM-06, JM-07, JM-08, JM-09, JM-11, JM-12, JM-13, JM-15, LE-02, LE-04, LE-05, LE-06, LE-07, LE-08, LE-09, LE-10, LE-12, TL-02, TL-03, TL-14, TL-16, YI-02, YI-03, YI-04, YI-05, YI-06, YI-07, YI-08, YI-09, YI-10 | N6: Core board for ages 5-14. Keep 10% spares.
A7: 2 | B7: Microcontrollers & Dev Boards | C7: ESP32 Dev Board + USB cable | D7: ESP32 DevKit V1 (Wi-Fi + Bluetooth) + micro-USB data cable | E7: Reusable | F7: =COUNTIF('Little Explorers 5-7'!$C:$C,$C7)+COUNTIF('Junior Makers 8-11'!$C:$C,$C7)+COUNTIF('Young Innovators 12-14'!$C:$C,$C7)+COUNTIF('Tech Leaders 15-17'!$C:$C,$C7) -> 10 | G7: =COUNTIF('Little Explorers 5-7'!$C:$C,$C7) -> 0 | H7: =COUNTIF('Junior Makers 8-11'!$C:$C,$C7) -> 0 | I7: =COUNTIF('Young Innovators 12-14'!$C:$C,$C7) -> 1 | J7: =COUNTIF('Tech Leaders 15-17'!$C:$C,$C7) -> 9 | K7: =MAX(_xlfn.MAXIFS('Little Explorers 5-7'!$D:$D,'Little Explorers 5-7'!$C:$C,$C7,'Little Explorers 5-7'!$E:$E,"Per group"),_xlfn.MAXIFS('Junior Makers 8-11'!$D:$D,'Junior Makers 8-11'!$C:$C,$C7,'Junior Makers 8-11'!$E:$E,"Per group"),_xlfn.MAXIFS('Young Innovators 12-14'!$D:$D,'Young Innovators 12-14'!$C:$C,$C7,'Young Innovators 12-14'!$E:$E,"Per group"),_xlfn.MAXIFS('Tech Leaders 15-17'!$D:$D,'Tech Leaders 15-17'!$C:$C,$C7,'Tech Leaders 15-17'!$E:$E,"Per group")) -> 4 | L7: =MAX(_xlfn.MAXIFS('Little Explorers 5-7'!$D:$D,'Little Explorers 5-7'!$C:$C,$C7,'Little Explorers 5-7'!$E:$E,"Per class"),_xlfn.MAXIFS('Junior Makers 8-11'!$D:$D,'Junior Makers 8-11'!$C:$C,$C7,'Junior Makers 8-11'!$E:$E,"Per class"),_xlfn.MAXIFS('Young Innovators 12-14'!$D:$D,'Young Innovators 12-14'!$C:$C,$C7,'Young Innovators 12-14'!$E:$E,"Per class"),_xlfn.MAXIFS('Tech Leaders 15-17'!$D:$D,'Tech Leaders 15-17'!$C:$C,$C7,'Tech Leaders 15-17'!$E:$E,"Per class")) -> 0 | M7: TL-01, TL-04, TL-05, TL-06, TL-07, TL-08, TL-09, TL-10, TL-12, YI-11 | N7: IoT and wireless builds, ages 12-17.
A8: 3 | B8: Microcontrollers & Dev Boards | C8: Makey Makey kit | D8: Makey Makey Classic (board, USB cable, 7 alligator clips) | E8: Reusable | F8: =COUNTIF('Little Explorers 5-7'!$C:$C,$C8)+COUNTIF('Junior Makers 8-11'!$C:$C,$C8)+COUNTIF('Young Innovators 12-14'!$C:$C,$C8)+COUNTIF('Tech Leaders 15-17'!$C:$C,$C8) -> 2 | G8: =COUNTIF('Little Explorers 5-7'!$C:$C,$C8) -> 2 | H8: =COUNTIF('Junior Makers 8-11'!$C:$C,$C8) -> 0 | I8: =COUNTIF('Young Innovators 12-14'!$C:$C,$C8) -> 0 | J8: =COUNTIF('Tech Leaders 15-17'!$C:$C,$C8) -> 0 | K8: =MAX(_xlfn.MAXIFS('Little Explorers 5-7'!$D:$D,'Little Explorers 5-7'!$C:$C,$C8,'Little Explorers 5-7'!$E:$E,"Per group"),_xlfn.MAXIFS('Junior Makers 8-11'!$D:$D,'Junior Makers 8-11'!$C:$C,$C8,'Junior Makers 8-11'!$E:$E,"Per group"),_xlfn.MAXIFS('Young Innovators 12-14'!$D:$D,'Young Innovators 12-14'!$C:$C,$C8,'Young Innovators 12-14'!$E:$E,"Per group"),_xlfn.MAXIFS('Tech Leaders 15-17'!$D:$D,'Tech Leaders 15-17'!$C:$C,$C8,'Tech Leaders 15-17'!$E:$E,"Per group")) -> 1 | L8: =MAX(_xlfn.MAXIFS('Little Explorers 5-7'!$D:$D,'Little Explorers 5-7'!$C:$C,$C8,'Little Explorers 5-7'!$E:$E,"Per class"),_xlfn.MAXIFS('Junior Makers 8-11'!$D:$D,'Junior Makers 8-11'!$C:$C,$C8,'Junior Makers 8-11'!$E:$E,"Per class"),_xlfn.MAXIFS('Young Innovators 12-14'!$D:$D,'Young Innovators 12-14'!$C:$C,$C8,'Young Innovators 12-14'!$E:$E,"Per class"),_xlfn.MAXIFS('Tech Leaders 15-17'!$D:$D,'Tech Leaders 15-17'!$C:$C,$C8,'Tech Leaders 15-17'!$E:$E,"Per class")) -> 0 | M8: LE-13, LE-15 | N8: Ages 5-7 interactive play.
B9: Robot Platforms & Kits (2 items)
A10: 4 | B10: Robot Platforms & Kits | C10: 2WD robot chassis kit | D10: 2WD acrylic chassis, 2 TT gear motors, wheels, castor, 4xAA holder | E10: Reusable | F10: =COUNTIF('Little Explorers 5-7'!$C:$C,$C10)+COUNTIF('Junior Makers 8-11'!$C:$C,$C10)+COUNTIF('Young Innovators 12-14'!$C:$C,$C10)+COUNTIF('Tech Leaders 15-17'!$C:$C,$C10) -> 5 | G10: =COUNTIF('Little Explorers 5-7'!$C:$C,$C10) -> 0 | H10: =COUNTIF('Junior Makers 8-11'!$C:$C,$C10) -> 1 | I10: =COUNTIF('Young Innovators 12-14'!$C:$C,$C10) -> 2 | J10: =COUNTIF('Tech Leaders 15-17'!$C:$C,$C10) -> 2 | K10: =MAX(_xlfn.MAXIFS('Little Explorers 5-7'!$D:$D,'Little Explorers 5-7'!$C:$C,$C10,'Little Explorers 5-7'!$E:$E,"Per group"),_xlfn.MAXIFS('Junior Makers 8-11'!$D:$D,'Junior Makers 8-11'!$C:$C,$C10,'Junior Makers 8-11'!$E:$E,"Per group"),_xlfn.MAXIFS('Young Innovators 12-14'!$D:$D,'Young Innovators 12-14'!$C:$C,$C10,'Young Innovators 12-14'!$E:$E,"Per group"),_xlfn.MAXIFS('Tech Leaders 15-17'!$D:$D,'Tech Leaders 15-17'!$C:$C,$C10,'Tech Leaders 15-17'!$E:$E,"Per group")) -> 1 | L10: =MAX(_xlfn.MAXIFS('Little Explorers 5-7'!$D:$D,'Little Explorers 5-7'!$C:$C,$C10,'Little Explorers 5-7'!$E:$E,"Per class"),_xlfn.MAXIFS('Junior Makers 8-11'!$D:$D,'Junior Makers 8-11'!$C:$C,$C10,'Junior Makers 8-11'!$E:$E,"Per class"),_xlfn.MAXIFS('Young Innovators 12-14'!$D:$D,'Young Innovators 12-14'!$C:$C,$C10,'Young Innovators 12-14'!$E:$E,"Per class"),_xlfn.MAXIFS('Tech Leaders 15-17'!$D:$D,'Tech Leaders 15-17'!$C:$C,$C10,'Tech Leaders 15-17'!$E:$E,"Per class")) -> 0 | M10: JM-11, TL-02, TL-14, YI-05, YI-06 | N10: Existing CodiBot kits can replace this.
A11: 5 | B11: Robot Platforms & Kits | C11: Brush Bot kit | D11: Toothbrush head + coin vibration motor + coin cell holder | E11: Consumable | F11: =COUNTIF('Little Explorers 5-7'!$C:$C,$C11)+COUNTIF('Junior Makers 8-11'!$C:$C,$C11)+COUNTIF('Young Innovators 12-14'!$C:$C,$C11)+COUNTIF('Tech Leaders 15-17'!$C:$C,$C11) -> 1 | G11: =COUNTIF('Little Explorers 5-7'!$C:$C,$C11) -> 1 | H11: =COUNTIF('Junior Makers 8-11'!$C:$C,$C11) -> 0 | I11: =COUNTIF('Young Innovators 12-14'!$C:$C,$C11) -> 0 | J11: =COUNTIF('Tech Leaders 15-17'!$C:$C,$C11) -> 0 | K11: =MAX(_xlfn.MAXIFS('Little Explorers 5-7'!$D:$D,'Little Explorers 5-7'!$C:$C,$C11,'Little Explorers 5-7'!$E:$E,"Per group"),_xlfn.MAXIFS('Junior Makers 8-11'!$D:$D,'Junior Makers 8-11'!$C:$C,$C11,'Junior Makers 8-11'!$E:$E,"Per group"),_xlfn.MAXIFS('Young Innovators 12-14'!$D:$D,'Young Innovators 12-14'!$C:$C,$C11,'Young Innovators 12-14'!$E:$E,"Per group"),_xlfn.MAXIFS('Tech Leaders 15-17'!$D:$D,'Tech Leaders 15-17'!$C:$C,$C11,'Tech Leaders 15-17'!$E:$E,"Per group")) -> 1 | L11: =MAX(_xlfn.MAXIFS('Little Explorers 5-7'!$D:$D,'Little Explorers 5-7'!$C:$C,$C11,'Little Explorers 5-7'!$E:$E,"Per class"),_xlfn.MAXIFS('Junior Makers 8-11'!$D:$D,'Junior Makers 8-11'!$C:$C,$C11,'Junior Makers 8-11'!$E:$E,"Per class"),_xlfn.MAXIFS('Young Innovators 12-14'!$D:$D,'Young Innovators 12-14'!$C:$C,$C11,'Young Innovators 12-14'!$E:$E,"Per class"),_xlfn.MAXIFS('Tech Leaders 15-17'!$D:$D,'Tech Leaders 15-17'!$C:$C,$C11,'Tech Leaders 15-17'!$E:$E,"Per class")) -> 0 | M11: LE-11
B12: Sensors (13 items)
A13: 6 | B13: Sensors | C13: Ultrasonic sensor HC-SR04 | D13: HC-SR04 ultrasonic distance sensor | E13: Reusable | F13: =COUNTIF('Little Explorers 5-7'!$C:$C,$C13)+COUNTIF('Junior Makers 8-11'!$C:$C,$C13)+COUNTIF('Young Innovators 12-14'!$C:$C,$C13)+COUNTIF('Tech Leaders 15-17'!$C:$C,$C13) -> 5 | G13: =COUNTIF('Little Explorers 5-7'!$C:$C,$C13) -> 1 | H13: =COUNTIF('Junior Makers 8-11'!$C:$C,$C13) -> 1 | I13: =COUNTIF('Young Innovators 12-14'!$C:$C,$C13) -> 1 | J13: =COUNTIF('Tech Leaders 15-17'!$C:$C,$C13) -> 2 | K13: =MAX(_xlfn.MAXIFS('Little Explorers 5-7'!$D:$D,'Little Explorers 5-7'!$C:$C,$C13,'Little Explorers 5-7'!$E:$E,"Per group"),_xlfn.MAXIFS('Junior Makers 8-11'!$D:$D,'Junior Makers 8-11'!$C:$C,$C13,'Junior Makers 8-11'!$E:$E,"Per group"),_xlfn.MAXIFS('Young Innovators 12-14'!$D:$D,'Young Innovators 12-14'!$C:$C,$C13,'Young Innovators 12-14'!$E:$E,"Per group"),_xlfn.MAXIFS('Tech Leaders 15-17'!$D:$D,'Tech Leaders 15-17'!$C:$C,$C13,'Tech Leaders 15-17'!$E:$E,"Per group")) -> 3 | L13: =MAX(_xlfn.MAXIFS('Little Explorers 5-7'!$D:$D,'Little Explorers 5-7'!$C:$C,$C13,'Little Explorers 5-7'!$E:$E,"Per class"),_xlfn.MAXIFS('Junior Makers 8-11'!$D:$D,'Junior Makers 8-11'!$C:$C,$C13,'Junior Makers 8-11'!$E:$E,"Per class"),_xlfn.MAXIFS('Young Innovators 12-14'!$D:$D,'Young Innovators 12-14'!$C:$C,$C13,'Young Innovators 12-14'!$E:$E,"Per class"),_xlfn.MAXIFS('Tech Leaders 15-17'!$D:$D,'Tech Leaders 15-17'!$C:$C,$C13,'Tech Leaders 15-17'!$E:$E,"Per class")) -> 0 | M13: JM-04, LE-10, TL-02, TL-07, YI-05 | N13: Most used sensor across all ages.
A14: 7 | B14: Sensors | C14: IR sensor module | D14: IR obstacle/line sensor (TCRT5000 or FC-51) | E14: Reusable | F14: =COUNTIF('Little Explorers 5-7'!$C:$C,$C14)+COUNTIF('Junior Makers 8-11'!$C:$C,$C14)+COUNTIF('Young Innovators 12-14'!$C:$C,$C14)+COUNTIF('Tech Leaders 15-17'!$C:$C,$C14) -> 1 | G14: =COUNTIF('Little Explorers 5-7'!$C:$C,$C14) -> 0 | H14: =COUNTIF('Junior Makers 8-11'!$C:$C,$C14) -> 1 | I14: =COUNTIF('Young Innovators 12-14'!$C:$C,$C14) -> 0 | J14: =COUNTIF('Tech Leaders 15-17'!$C:$C,$C14) -> 0 | K14: =MAX(_xlfn.MAXIFS('Little Explorers 5-7'!$D:$D,'Little Explorers 5-7'!$C:$C,$C14,'Little Explorers 5-7'!$E:$E,"Per group"),_xlfn.MAXIFS('Junior Makers 8-11'!$D:$D,'Junior Makers 8-11'!$C:$C,$C14,'Junior Makers 8-11'!$E:$E,"Per group"),_xlfn.MAXIFS('Young Innovators 12-14'!$D:$D,'Young Innovators 12-14'!$C:$C,$C14,'Young Innovators 12-14'!$E:$E,"Per group"),_xlfn.MAXIFS('Tech Leaders 15-17'!$D:$D,'Tech Leaders 15-17'!$C:$C,$C14,'Tech Leaders 15-17'!$E:$E,"Per group")) -> 2 | L14: =MAX(_xlfn.MAXIFS('Little Explorers 5-7'!$D:$D,'Little Explorers 5-7'!$C:$C,$C14,'Little Explorers 5-7'!$E:$E,"Per class"),_xlfn.MAXIFS('Junior Makers 8-11'!$D:$D,'Junior Makers 8-11'!$C:$C,$C14,'Junior Makers 8-11'!$E:$E,"Per class"),_xlfn.MAXIFS('Young Innovators 12-14'!$D:$D,'Young Innovators 12-14'!$C:$C,$C14,'Young Innovators 12-14'!$E:$E,"Per class"),_xlfn.MAXIFS('Tech Leaders 15-17'!$D:$D,'Tech Leaders 15-17'!$C:$C,$C14,'Tech Leaders 15-17'!$E:$E,"Per class")) -> 0 | M14: JM-11
A15: 8 | B15: Sensors | C15: LDR module | D15: LDR light sensor (module or LDR + 10k resistor) | E15: Reusable | F15: =COUNTIF('Little Explorers 5-7'!$C:$C,$C15)+COUNTIF('Junior Makers 8-11'!$C:$C,$C15)+COUNTIF('Young Innovators 12-14'!$C:$C,$C15)+COUNTIF('Tech Leaders 15-17'!$C:$C,$C15) -> 7 | G15: =COUNTIF('Little Explorers 5-7'!$C:$C,$C15) -> 1 | H15: =COUNTIF('Junior Makers 8-11'!$C:$C,$C15) -> 2 | I15: =COUNTIF('Young Innovators 12-14'!$C:$C,$C15) -> 1 | J15: =COUNTIF('Tech Leaders 15-17'!$C:$C,$C15) -> 3 | K15: =MAX(_xlfn.MAXIFS('Little Explorers 5-7'!$D:$D,'Little Explorers 5-7'!$C:$C,$C15,'Little Explorers 5-7'!$E:$E,"Per group"),_xlfn.MAXIFS('Junior Makers 8-11'!$D:$D,'Junior Makers 8-11'!$C:$C,$C15,'Junior Makers 8-11'!$E:$E,"Per group"),_xlfn.MAXIFS('Young Innovators 12-14'!$D:$D,'Young Innovators 12-14'!$C:$C,$C15,'Young Innovators 12-14'!$E:$E,"Per group"),_xlfn.MAXIFS('Tech Leaders 15-17'!$D:$D,'Tech Leaders 15-17'!$C:$C,$C15,'Tech Leaders 15-17'!$E:$E,"Per group")) -> 2 | L15: =MAX(_xlfn.MAXIFS('Little Explorers 5-7'!$D:$D,'Little Explorers 5-7'!$C:$C,$C15,'Little Explorers 5-7'!$E:$E,"Per class"),_xlfn.MAXIFS('Junior Makers 8-11'!$D:$D,'Junior Makers 8-11'!$C:$C,$C15,'Junior Makers 8-11'!$E:$E,"Per class"),_xlfn.MAXIFS('Young Innovators 12-14'!$D:$D,'Young Innovators 12-14'!$C:$C,$C15,'Young Innovators 12-14'!$E:$E,"Per class"),_xlfn.MAXIFS('Tech Leaders 15-17'!$D:$D,'Tech Leaders 15-17'!$C:$C,$C15,'Tech Leaders 15-17'!$E:$E,"Per class")) -> 0 | M15: JM-03, JM-08, LE-05, TL-05, TL-09, TL-10, YI-03
A16: 9 | B16: Sensors | C16: DHT22 sensor | D16: DHT22 temperature & humidity sensor | E16: Reusable | F16: =COUNTIF('Little Explorers 5-7'!$C:$C,$C16)+COUNTIF('Junior Makers 8-11'!$C:$C,$C16)+COUNTIF('Young Innovators 12-14'!$C:$C,$C16)+COUNTIF('Tech Leaders 15-17'!$C:$C,$C16) -> 10 | G16: =COUNTIF('Little Explorers 5-7'!$C:$C,$C16) -> 1 | H16: =COUNTIF('Junior Makers 8-11'!$C:$C,$C16) -> 2 | I16: =COUNTIF('Young Innovators 12-14'!$C:$C,$C16) -> 1 | J16: =COUNTIF('Tech Leaders 15-17'!$C:$C,$C16) -> 6 | K16: =MAX(_xlfn.MAXIFS('Little Explorers 5-7'!$D:$D,'Little Explorers 5-7'!$C:$C,$C16,'Little Explorers 5-7'!$E:$E,"Per group"),_xlfn.MAXIFS('Junior Makers 8-11'!$D:$D,'Junior Makers 8-11'!$C:$C,$C16,'Junior Makers 8-11'!$E:$E,"Per group"),_xlfn.MAXIFS('Young Innovators 12-14'!$D:$D,'Young Innovators 12-14'!$C:$C,$C16,'Young Innovators 12-14'!$E:$E,"Per group"),_xlfn.MAXIFS('Tech Leaders 15-17'!$D:$D,'Tech Leaders 15-17'!$C:$C,$C16,'Tech Leaders 15-17'!$E:$E,"Per group")) -> 1 | L16: =MAX(_xlfn.MAXIFS('Little Explorers 5-7'!$D:$D,'Little Explorers 5-7'!$C:$C,$C16,'Little Explorers 5-7'!$E:$E,"Per class"),_xlfn.MAXIFS('Junior Makers 8-11'!$D:$D,'Junior Makers 8-11'!$C:$C,$C16,'Junior Makers 8-11'!$E:$E,"Per class"),_xlfn.MAXIFS('Young Innovators 12-14'!$D:$D,'Young Innovators 12-14'!$C:$C,$C16,'Young Innovators 12-14'!$E:$E,"Per class"),_xlfn.MAXIFS('Tech Leaders 15-17'!$D:$D,'Tech Leaders 15-17'!$C:$C,$C16,'Tech Leaders 15-17'!$E:$E,"Per class")) -> 0 | M16: JM-03, JM-07, LE-06, TL-01, TL-05, TL-06, TL-09, TL-10, TL-12, YI-11 | N16: Also works in the Wokwi simulator.
A17: 10 | B17: Sensors | C17: MQ-2 gas sensor | D17: MQ-2 smoke/LPG gas module | E17: Reusable | F17: =COUNTIF('Little Explorers 5-7'!$C:$C,$C17)+COUNTIF('Junior Makers 8-11'!$C:$C,$C17)+COUNTIF('Young Innovators 12-14'!$C:$C,$C17)+COUNTIF('Tech Leaders 15-17'!$C:$C,$C17) -> 1 | G17: =COUNTIF('Little Explorers 5-7'!$C:$C,$C17) -> 0 | H17: =COUNTIF('Junior Makers 8-11'!$C:$C,$C17) -> 1 | I17: =COUNTIF('Young Innovators 12-14'!$C:$C,$C17) -> 0 | J17: =COUNTIF('Tech Leaders 15-17'!$C:$C,$C17) -> 0 | K17: =MAX(_xlfn.MAXIFS('Little Explorers 5-7'!$D:$D,'Little Explorers 5-7'!$C:$C,$C17,'Little Explorers 5-7'!$E:$E,"Per group"),_xlfn.MAXIFS('Junior Makers 8-11'!$D:$D,'Junior Makers 8-11'!$C:$C,$C17,'Junior Makers 8-11'!$E:$E,"Per group"),_xlfn.MAXIFS('Young Innovators 12-14'!$D:$D,'Young Innovators 12-14'!$C:$C,$C17,'Young Innovators 12-14'!$E:$E,"Per group"),_xlfn.MAXIFS('Tech Leaders 15-17'!$D:$D,'Tech Leaders 15-17'!$C:$C,$C17,'Tech Leaders 15-17'!$E:$E,"Per group")) -> 1 | L17: =MAX(_xlfn.MAXIFS('Little Explorers 5-7'!$D:$D,'Little Explorers 5-7'!$C:$C,$C17,'Little Explorers 5-7'!$E:$E,"Per class"),_xlfn.MAXIFS('Junior Makers 8-11'!$D:$D,'Junior Makers 8-11'!$C:$C,$C17,'Junior Makers 8-11'!$E:$E,"Per class"),_xlfn.MAXIFS('Young Innovators 12-14'!$D:$D,'Young Innovators 12-14'!$C:$C,$C17,'Young Innovators 12-14'!$E:$E,"Per class"),_xlfn.MAXIFS('Tech Leaders 15-17'!$D:$D,'Tech Leaders 15-17'!$C:$C,$C17,'Tech Leaders 15-17'!$E:$E,"Per class")) -> 0 | M17: JM-06 | N17: Needs 24-48 h burn-in; gas demo teacher-operated.
A18: 11 | B18: Sensors | C18: Flame sensor | D18: IR flame sensor module | E18: Reusable | F18: =COUNTIF('Little Explorers 5-7'!$C:$C,$C18)+COUNTIF('Junior Makers 8-11'!$C:$C,$C18)+COUNTIF('Young Innovators 12-14'!$C:$C,$C18)+COUNTIF('Tech Leaders 15-17'!$C:$C,$C18) -> 2 | G18: =COUNTIF('Little Explorers 5-7'!$C:$C,$C18) -> 0 | H18: =COUNTIF('Junior Makers 8-11'!$C:$C,$C18) -> 1 | I18: =COUNTIF('Young Innovators 12-14'!$C:$C,$C18) -> 0 | J18: =COUNTIF('Tech Leaders 15-17'!$C:$C,$C18) -> 1 | K18: =MAX(_xlfn.MAXIFS('Little Explorers 5-7'!$D:$D,'Little Explorers 5-7'!$C:$C,$C18,'Little Explorers 5-7'!$E:$E,"Per group"),_xlfn.MAXIFS('Junior Makers 8-11'!$D:$D,'Junior Makers 8-11'!$C:$C,$C18,'Junior Makers 8-11'!$E:$E,"Per group"),_xlfn.MAXIFS('Young Innovators 12-14'!$D:$D,'Young Innovators 12-14'!$C:$C,$C18,'Young Innovators 12-14'!$E:$E,"Per group"),_xlfn.MAXIFS('Tech Leaders 15-17'!$D:$D,'Tech Leaders 15-17'!$C:$C,$C18,'Tech Leaders 15-17'!$E:$E,"Per group")) -> 3 | L18: =MAX(_xlfn.MAXIFS('Little Explorers 5-7'!$D:$D,'Little Explorers 5-7'!$C:$C,$C18,'Little Explorers 5-7'!$E:$E,"Per class"),_xlfn.MAXIFS('Junior Makers 8-11'!$D:$D,'Junior Makers 8-11'!$C:$C,$C18,'Junior Makers 8-11'!$E:$E,"Per class"),_xlfn.MAXIFS('Young Innovators 12-14'!$D:$D,'Young Innovators 12-14'!$C:$C,$C18,'Young Innovators 12-14'!$E:$E,"Per class"),_xlfn.MAXIFS('Tech Leaders 15-17'!$D:$D,'Tech Leaders 15-17'!$C:$C,$C18,'Tech Leaders 15-17'!$E:$E,"Per class")) -> 0 | M18: JM-06, TL-14 | N18: Use a candle only under teacher supervision.
A19: 12 | B19: Sensors | C19: Rain sensor | D19: Rain/water-drop sensor with control board | E19: Reusable | F19: =COUNTIF('Little Explorers 5-7'!$C:$C,$C19)+COUNTIF('Junior Makers 8-11'!$C:$C,$C19)+COUNTIF('Young Innovators 12-14'!$C:$C,$C19)+COUNTIF('Tech Leaders 15-17'!$C:$C,$C19) -> 2 | G19: =COUNTIF('Little Explorers 5-7'!$C:$C,$C19) -> 0 | H19: =COUNTIF('Junior Makers 8-11'!$C:$C,$C19) -> 1 | I19: =COUNTIF('Young Innovators 12-14'!$C:$C,$C19) -> 0 | J19: =COUNTIF('Tech Leaders 15-17'!$C:$C,$C19) -> 1 | K19: =MAX(_xlfn.MAXIFS('Little Explorers 5-7'!$D:$D,'Little Explorers 5-7'!$C:$C,$C19,'Little Explorers 5-7'!$E:$E,"Per group"),_xlfn.MAXIFS('Junior Makers 8-11'!$D:$D,'Junior Makers 8-11'!$C:$C,$C19,'Junior Makers 8-11'!$E:$E,"Per group"),_xlfn.MAXIFS('Young Innovators 12-14'!$D:$D,'Young Innovators 12-14'!$C:$C,$C19,'Young Innovators 12-14'!$E:$E,"Per group"),_xlfn.MAXIFS('Tech Leaders 15-17'!$D:$D,'Tech Leaders 15-17'!$C:$C,$C19,'Tech Leaders 15-17'!$E:$E,"Per group")) -> 1 | L19: =MAX(_xlfn.MAXIFS('Little Explorers 5-7'!$D:$D,'Little Explorers 5-7'!$C:$C,$C19,'Little Explorers 5-7'!$E:$E,"Per class"),_xlfn.MAXIFS('Junior Makers 8-11'!$D:$D,'Junior Makers 8-11'!$C:$C,$C19,'Junior Makers 8-11'!$E:$E,"Per class"),_xlfn.MAXIFS('Young Innovators 12-14'!$D:$D,'Young Innovators 12-14'!$C:$C,$C19,'Young Innovators 12-14'!$E:$E,"Per class"),_xlfn.MAXIFS('Tech Leaders 15-17'!$D:$D,'Tech Leaders 15-17'!$C:$C,$C19,'Tech Leaders 15-17'!$E:$E,"Per class")) -> 0 | M19: JM-05, TL-10
A20: 13 | B20: Sensors | C20: Soil moisture sensor | D20: Capacitive soil moisture sensor | E20: Reusable | F20: =COUNTIF('Little Explorers 5-7'!$C:$C,$C20)+COUNTIF('Junior Makers 8-11'!$C:$C,$C20)+COUNTIF('Young Innovators 12-14'!$C:$C,$C20)+COUNTIF('Tech Leaders 15-17'!$C:$C,$C20) -> 2 | G20: =COUNTIF('Little Explorers 5-7'!$C:$C,$C20) -> 1 | H20: =COUNTIF('Junior Makers 8-11'!$C:$C,$C20) -> 0 | I20: =COUNTIF('Young Innovators 12-14'!$C:$C,$C20) -> 1 | J20: =COUNTIF('Tech Leaders 15-17'!$C:$C,$C20) -> 0 | K20: =MAX(_xlfn.MAXIFS('Little Explorers 5-7'!$D:$D,'Little Explorers 5-7'!$C:$C,$C20,'Little Explorers 5-7'!$E:$E,"Per group"),_xlfn.MAXIFS('Junior Makers 8-11'!$D:$D,'Junior Makers 8-11'!$C:$C,$C20,'Junior Makers 8-11'!$E:$E,"Per group"),_xlfn.MAXIFS('Young Innovators 12-14'!$D:$D,'Young Innovators 12-14'!$C:$C,$C20,'Young Innovators 12-14'!$E:$E,"Per group"),_xlfn.MAXIFS('Tech Leaders 15-17'!$D:$D,'Tech Leaders 15-17'!$C:$C,$C20,'Tech Leaders 15-17'!$E:$E,"Per group")) -> 1 | L20: =MAX(_xlfn.MAXIFS('Little Explorers 5-7'!$D:$D,'Little Explorers 5-7'!$C:$C,$C20,'Little Explorers 5-7'!$E:$E,"Per class"),_xlfn.MAXIFS('Junior Makers 8-11'!$D:$D,'Junior Makers 8-11'!$C:$C,$C20,'Junior Makers 8-11'!$E:$E,"Per class"),_xlfn.MAXIFS('Young Innovators 12-14'!$D:$D,'Young Innovators 12-14'!$C:$C,$C20,'Young Innovators 12-14'!$E:$E,"Per class"),_xlfn.MAXIFS('Tech Leaders 15-17'!$D:$D,'Tech Leaders 15-17'!$C:$C,$C20,'Tech Leaders 15-17'!$E:$E,"Per class")) -> 0 | M20: LE-07, YI-11
A21: 14 | B21: Sensors | C21: Sound sensor KY-037 | D21: KY-037 microphone sound sensor | E21: Reusable | F21: =COUNTIF('Little Explorers 5-7'!$C:$C,$C21)+COUNTIF('Junior Makers 8-11'!$C:$C,$C21)+COUNTIF('Young Innovators 12-14'!$C:$C,$C21)+COUNTIF('Tech Leaders 15-17'!$C:$C,$C21) -> 2 | G21: =COUNTIF('Little Explorers 5-7'!$C:$C,$C21) -> 0 | H21: =COUNTIF('Junior Makers 8-11'!$C:$C,$C21) -> 0 | I21: =COUNTIF('Young Innovators 12-14'!$C:$C,$C21) -> 0 | J21: =COUNTIF('Tech Leaders 15-17'!$C:$C,$C21) -> 2 | K21: =MAX(_xlfn.MAXIFS('Little Explorers 5-7'!$D:$D,'Little Explorers 5-7'!$C:$C,$C21,'Little Explorers 5-7'!$E:$E,"Per group"),_xlfn.MAXIFS('Junior Makers 8-11'!$D:$D,'Junior Makers 8-11'!$C:$C,$C21,'Junior Makers 8-11'!$E:$E,"Per group"),_xlfn.MAXIFS('Young Innovators 12-14'!$D:$D,'Young Innovators 12-14'!$C:$C,$C21,'Young Innovators 12-14'!$E:$E,"Per group"),_xlfn.MAXIFS('Tech Leaders 15-17'!$D:$D,'Tech Leaders 15-17'!$C:$C,$C21,'Tech Leaders 15-17'!$E:$E,"Per group")) -> 1 | L21: =MAX(_xlfn.MAXIFS('Little Explorers 5-7'!$D:$D,'Little Explorers 5-7'!$C:$C,$C21,'Little Explorers 5-7'!$E:$E,"Per class"),_xlfn.MAXIFS('Junior Makers 8-11'!$D:$D,'Junior Makers 8-11'!$C:$C,$C21,'Junior Makers 8-11'!$E:$E,"Per class"),_xlfn.MAXIFS('Young Innovators 12-14'!$D:$D,'Young Innovators 12-14'!$C:$C,$C21,'Young Innovators 12-14'!$E:$E,"Per class"),_xlfn.MAXIFS('Tech Leaders 15-17'!$D:$D,'Tech Leaders 15-17'!$C:$C,$C21,'Tech Leaders 15-17'!$E:$E,"Per class")) -> 0 | M21: TL-05, TL-09
A22: 15 | B22: Sensors | C22: Pulse sensor | D22: Heart-rate pulse sensor (optical) | E22: Reusable | F22: =COUNTIF('Little Explorers 5-7'!$C:$C,$C22)+COUNTIF('Junior Makers 8-11'!$C:$C,$C22)+COUNTIF('Young Innovators 12-14'!$C:$C,$C22)+COUNTIF('Tech Leaders 15-17'!$C:$C,$C22) -> 1 | G22: =COUNTIF('Little Explorers 5-7'!$C:$C,$C22) -> 0 | H22: =COUNTIF('Junior Makers 8-11'!$C:$C,$C22) -> 0 | I22: =COUNTIF('Young Innovators 12-14'!$C:$C,$C22) -> 1 | J22: =COUNTIF('Tech Leaders 15-17'!$C:$C,$C22) -> 0 | K22: =MAX(_xlfn.MAXIFS('Little Explorers 5-7'!$D:$D,'Little Explorers 5-7'!$C:$C,$C22,'Little Explorers 5-7'!$E:$E,"Per group"),_xlfn.MAXIFS('Junior Makers 8-11'!$D:$D,'Junior Makers 8-11'!$C:$C,$C22,'Junior Makers 8-11'!$E:$E,"Per group"),_xlfn.MAXIFS('Young Innovators 12-14'!$D:$D,'Young Innovators 12-14'!$C:$C,$C22,'Young Innovators 12-14'!$E:$E,"Per group"),_xlfn.MAXIFS('Tech Leaders 15-17'!$D:$D,'Tech Leaders 15-17'!$C:$C,$C22,'Tech Leaders 15-17'!$E:$E,"Per group")) -> 1 | L22: =MAX(_xlfn.MAXIFS('Little Explorers 5-7'!$D:$D,'Little Explorers 5-7'!$C:$C,$C22,'Little Explorers 5-7'!$E:$E,"Per class"),_xlfn.MAXIFS('Junior Makers 8-11'!$D:$D,'Junior Makers 8-11'!$C:$C,$C22,'Junior Makers 8-11'!$E:$E,"Per class"),_xlfn.MAXIFS('Young Innovators 12-14'!$D:$D,'Young Innovators 12-14'!$C:$C,$C22,'Young Innovators 12-14'!$E:$E,"Per class"),_xlfn.MAXIFS('Tech Leaders 15-17'!$D:$D,'Tech Leaders 15-17'!$C:$C,$C22,'Tech Leaders 15-17'!$E:$E,"Per class")) -> 0 | M22: YI-02
A23: 16 | B23: Sensors | C23: PIR motion sensor | D23: HC-SR501 PIR motion sensor | E23: Reusable | F23: =COUNTIF('Little Explorers 5-7'!$C:$C,$C23)+COUNTIF('Junior Makers 8-11'!$C:$C,$C23)+COUNTIF('Young Innovators 12-14'!$C:$C,$C23)+COUNTIF('Tech Leaders 15-17'!$C:$C,$C23) -> 5 | G23: =COUNTIF('Little Explorers 5-7'!$C:$C,$C23) -> 1 | H23: =COUNTIF('Junior Makers 8-11'!$C:$C,$C23) -> 1 | I23: =COUNTIF('Young Innovators 12-14'!$C:$C,$C23) -> 1 | J23: =COUNTIF('Tech Leaders 15-17'!$C:$C,$C23) -> 2 | K23: =MAX(_xlfn.MAXIFS('Little Explorers 5-7'!$D:$D,'Little Explorers 5-7'!$C:$C,$C23,'Little Explorers 5-7'!$E:$E,"Per group"),_xlfn.MAXIFS('Junior Makers 8-11'!$D:$D,'Junior Makers 8-11'!$C:$C,$C23,'Junior Makers 8-11'!$E:$E,"Per group"),_xlfn.MAXIFS('Young Innovators 12-14'!$D:$D,'Young Innovators 12-14'!$C:$C,$C23,'Young Innovators 12-14'!$E:$E,"Per group"),_xlfn.MAXIFS('Tech Leaders 15-17'!$D:$D,'Tech Leaders 15-17'!$C:$C,$C23,'Tech Leaders 15-17'!$E:$E,"Per group")) -> 1 | L23: =MAX(_xlfn.MAXIFS('Little Explorers 5-7'!$D:$D,'Little Explorers 5-7'!$C:$C,$C23,'Little Explorers 5-7'!$E:$E,"Per class"),_xlfn.MAXIFS('Junior Makers 8-11'!$D:$D,'Junior Makers 8-11'!$C:$C,$C23,'Junior Makers 8-11'!$E:$E,"Per class"),_xlfn.MAXIFS('Young Innovators 12-14'!$D:$D,'Young Innovators 12-14'!$C:$C,$C23,'Young Innovators 12-14'!$E:$E,"Per class"),_xlfn.MAXIFS('Tech Leaders 15-17'!$D:$D,'Tech Leaders 15-17'!$C:$C,$C23,'Tech Leaders 15-17'!$E:$E,"Per class")) -> 0 | M23: JM-09, LE-08, TL-06, TL-08, YI-03
A24: 17 | B24: Sensors | C24: MPU6050 IMU | D24: MPU6050 accelerometer + gyroscope (GY-521) | E24: Reusable | F24: =COUNTIF('Little Explorers 5-7'!$C:$C,$C24)+COUNTIF('Junior Makers 8-11'!$C:$C,$C24)+COUNTIF('Young Innovators 12-14'!$C:$C,$C24)+COUNTIF('Tech Leaders 15-17'!$C:$C,$C24) -> 3 | G24: =COUNTIF('Little Explorers 5-7'!$C:$C,$C24) -> 0 | H24: =COUNTIF('Junior Makers 8-11'!$C:$C,$C24) -> 1 | I24: =COUNTIF('Young Innovators 12-14'!$C:$C,$C24) -> 1 | J24: =COUNTIF('Tech Leaders 15-17'!$C:$C,$C24) -> 1 | K24: =MAX(_xlfn.MAXIFS('Little Explorers 5-7'!$D:$D,'Little Explorers 5-7'!$C:$C,$C24,'Little Explorers 5-7'!$E:$E,"Per group"),_xlfn.MAXIFS('Junior Makers 8-11'!$D:$D,'Junior Makers 8-11'!$C:$C,$C24,'Junior Makers 8-11'!$E:$E,"Per group"),_xlfn.MAXIFS('Young Innovators 12-14'!$D:$D,'Young Innovators 12-14'!$C:$C,$C24,'Young Innovators 12-14'!$E:$E,"Per group"),_xlfn.MAXIFS('Tech Leaders 15-17'!$D:$D,'Tech Leaders 15-17'!$C:$C,$C24,'Tech Leaders 15-17'!$E:$E,"Per group")) -> 1 | L24: =MAX(_xlfn.MAXIFS('Little Explorers 5-7'!$D:$D,'Little Explorers 5-7'!$C:$C,$C24,'Little Explorers 5-7'!$E:$E,"Per class"),_xlfn.MAXIFS('Junior Makers 8-11'!$D:$D,'Junior Makers 8-11'!$C:$C,$C24,'Junior Makers 8-11'!$E:$E,"Per class"),_xlfn.MAXIFS('Young Innovators 12-14'!$D:$D,'Young Innovators 12-14'!$C:$C,$C24,'Young Innovators 12-14'!$E:$E,"Per class"),_xlfn.MAXIFS('Tech Leaders 15-17'!$D:$D,'Tech Leaders 15-17'!$C:$C,$C24,'Tech Leaders 15-17'!$E:$E,"Per class")) -> 0 | M24: JM-13, TL-04, YI-07 | N24: Order pre-soldered headers.
A25: 18 | B25: Sensors | C25: Joystick module | D25: KY-023 dual-axis joystick | E25: Reusable | F25: =COUNTIF('Little Explorers 5-7'!$C:$C,$C25)+COUNTIF('Junior Makers 8-11'!$C:$C,$C25)+COUNTIF('Young Innovators 12-14'!$C:$C,$C25)+COUNTIF('Tech Leaders 15-17'!$C:$C,$C25) -> 1 | G25: =COUNTIF('Little Explorers 5-7'!$C:$C,$C25) -> 0 | H25: =COUNTIF('Junior Makers 8-11'!$C:$C,$C25) -> 0 | I25: =COUNTIF('Young Innovators 12-14'!$C:$C,$C25) -> 0 | J25: =COUNTIF('Tech Leaders 15-17'!$C:$C,$C25) -> 1 | K25: =MAX(_xlfn.MAXIFS('Little Explorers 5-7'!$D:$D,'Little Explorers 5-7'!$C:$C,$C25,'Little Explorers 5-7'!$E:$E,"Per group"),_xlfn.MAXIFS('Junior Makers 8-11'!$D:$D,'Junior Makers 8-11'!$C:$C,$C25,'Junior Makers 8-11'!$E:$E,"Per group"),_xlfn.MAXIFS('Young Innovators 12-14'!$D:$D,'Young Innovators 12-14'!$C:$C,$C25,'Young Innovators 12-14'!$E:$E,"Per group"),_xlfn.MAXIFS('Tech Leaders 15-17'!$D:$D,'Tech Leaders 15-17'!$C:$C,$C25,'Tech Leaders 15-17'!$E:$E,"Per group")) -> 1 | L25: =MAX(_xlfn.MAXIFS('Little Explorers 5-7'!$D:$D,'Little Explorers 5-7'!$C:$C,$C25,'Little Explorers 5-7'!$E:$E,"Per class"),_xlfn.MAXIFS('Junior Makers 8-11'!$D:$D,'Junior Makers 8-11'!$C:$C,$C25,'Junior Makers 8-11'!$E:$E,"Per class"),_xlfn.MAXIFS('Young Innovators 12-14'!$D:$D,'Young Innovators 12-14'!$C:$C,$C25,'Young Innovators 12-14'!$E:$E,"Per class"),_xlfn.MAXIFS('Tech Leaders 15-17'!$D:$D,'Tech Leaders 15-17'!$C:$C,$C25,'Tech Leaders 15-17'!$E:$E,"Per class")) -> 0 | M25: TL-16
B26: Security & Identification (2 items)
