Workbook

Sheet How to Use
B2: Robotics & AI Club: Weekly Planner and Hardware Sheet
B3: Curriculum developed by Qasim Mushtaq, MS Robotics and AI · Academic Year 2026-27
B5: Every Friday
B6: 1. Session Tracker | C6: For each session next week: Status = 'Next week', choose the Day, and check 'Groups (pairs)' (default 8). Add time and section if you like.
B7: 2. This Week's Hardware | C7: Type next Monday's date in the yellow cell. Part A lists the sessions, Part B lists the hardware DAY BY DAY (all sessions on that day added together).
B8: Daily Kit Lists | C8: Day by day, then each session in the same format as the kit tabs (Code, Category, Component, Qty, Basis, Type, Notes) with the total to pack. Every Arduino class also gets an LED, a 220 ohm resistor and a buzzer.
B9: 3. Print | C9: Print 'This Week's Hardware' (A4, it only prints the filled rows) and give it to the lab assistant. They tick Issued and Returned.
B10: After each session | C10: Change Status to 'Done' (it turns green and drops off next week's list) and add notes.
B12: How quantities work
B13: Per group | C13: Qty x number of groups in that session. One group = 2 students.
B14: Per class | C14: Shared items (glue gun, 3D printer). Counted once per session.
B15: Reusable items | C15: Issue qty = the most needed on any ONE day, because kits come back and are reused the next day.
B16: Consumables | C16: Issue qty = the total for the whole week (they are used up).
B17: No day set | C17: A session marked Next week without a Day is still counted, as an extra on top of the busiest day.
B19: Tabs
B20: Session Tracker | C20: All activities for all 4 pathways: Foundation classes (F-00 Welcome to Robotics, F-01 Arduino Uno, F-02 ESP32, F-03 3D printing) for every age group, Phase 1 (classes 1-16), Phase 2 (17-32) and the JM-00 Art Bot intro. Click a code to open its kit.
B21: LE / JM / YI / TL Kits | C21: Hardware per activity. Edit columns A-G to change a kit; the weekly sheet follows automatically. Each activity header shows its current status.
B22: Calc | C22: Automatic totals per component. Only touch it to add a brand-new component name.
B24: Example | C24: Friday 9 Oct: JM-06 Fire & Gas Alarm set to Next week, Day = Tue, Groups = 8 -> the weekly sheet asks for 8 Arduino Unos, 8 MQ-2 sensors, 8 flame sensors... for Tuesday 13 Oct.
B26: Yellow cells = you edit. Grey cells = automatic, do not type over them.

Sheet This Week's Hardware
A1: Robotics & AI Club: Hardware Request for the Week | J1: Received by (lab):
A2: Pak-Turk Maarif International Schools & Colleges, Chak Shahzad Campus · Robotics Lab | J2: Signature / date:
A3: Week starting (Monday): | D3: Requested by: | F3: Qasim Mushtaq
A4: =COUNT('Session Tracker'!$M$5:$M$149)&" session(s) marked Next week · "&COUNTIF(Calc!$M$3:$M$101,">0")&" different items this week" -> 0 session(s) marked Next week · 0 different items this week | I4: =IF(SUM(Calc!K3:K101)<>SUM('Little Explorers Kits'!H5:M358)+SUM('Junior Makers Kits'!H5:M440)+SUM('Young Innovators Kits'!H5:M418)+SUM('Tech Leaders Kits'!H5:M386),"Warning: a kit tab has a component name that is missing from the Calc tab","")
A6: A. Sessions next week
A7: # | B7: Day / date | C7: Activity | D7: Code | E7: Time | G7: Pathway | J7: Groups | K7: Section / class
A8: =IF(1<=COUNT('Session Tracker'!$M$5:$M$149),1,"") | B8: =IF($A8="","",IF(IFERROR(INDEX('Session Tracker'!$G$5:$G$149,MATCH(SMALL('Session Tracker'!$M$5:$M$149,$A8),'Session Tracker'!$M$5:$M$149,0)),"")="","Day not set",IFERROR(INDEX('Session Tracker'!$G$5:$G$149,MATCH(SMALL('Session Tracker'!$M$5:$M$149,$A8),'Session Tracker'!$M$5:$M$149,0)),"")&IF($C$3="",""," "&TEXT($C$3+MATCH(IFERROR(INDEX('Session Tracker'!$G$5:$G$149,MATCH(SMALL('Session Tracker'!$M$5:$M$149,$A8),'Session Tracker'!$M$5:$M$149,0)),""),{"Mon","Tue","Wed","Thu","Fri"},0)-1,"dd-mmm")))) | C8: =IF($A8="","",IFERROR(INDEX('Session Tracker'!$E$5:$E$149,MATCH(SMALL('Session Tracker'!$M$5:$M$149,$A8),'Session Tracker'!$M$5:$M$149,0)),"")) | D8: =IF($A8="","",IFERROR(INDEX('Session Tracker'!$D$5:$D$149,MATCH(SMALL('Session Tracker'!$M$5:$M$149,$A8),'Session Tracker'!$M$5:$M$149,0)),"")) | E8: =IF($A8="","",IFERROR(INDEX('Session Tracker'!$H$5:$H$149,MATCH(SMALL('Session Tracker'!$M$5:$M$149,$A8),'Session Tracker'!$M$5:$M$149,0)),"")&"") | G8: =IF($A8="","",IFERROR(INDEX('Session Tracker'!$A$5:$A$149,MATCH(SMALL('Session Tracker'!$M$5:$M$149,$A8),'Session Tracker'!$M$5:$M$149,0)),"")) | J8: =IF($A8="","",IFERROR(INDEX('Session Tracker'!$J$5:$J$149,MATCH(SMALL('Session Tracker'!$M$5:$M$149,$A8),'Session Tracker'!$M$5:$M$149,0)),"")) | K8: =IF($A8="","",IFERROR(INDEX('Session Tracker'!$I$5:$I$149,MATCH(SMALL('Session Tracker'!$M$5:$M$149,$A8),'Session Tracker'!$M$5:$M$149,0)),"")&"")
A9: =IF(2<=COUNT('Session Tracker'!$M$5:$M$149),2,"") | B9: =IF($A9="","",IF(IFERROR(INDEX('Session Tracker'!$G$5:$G$149,MATCH(SMALL('Session Tracker'!$M$5:$M$149,$A9),'Session Tracker'!$M$5:$M$149,0)),"")="","Day not set",IFERROR(INDEX('Session Tracker'!$G$5:$G$149,MATCH(SMALL('Session Tracker'!$M$5:$M$149,$A9),'Session Tracker'!$M$5:$M$149,0)),"")&IF($C$3="",""," "&TEXT($C$3+MATCH(IFERROR(INDEX('Session Tracker'!$G$5:$G$149,MATCH(SMALL('Session Tracker'!$M$5:$M$149,$A9),'Session Tracker'!$M$5:$M$149,0)),""),{"Mon","Tue","Wed","Thu","Fri"},0)-1,"dd-mmm")))) | C9: =IF($A9="","",IFERROR(INDEX('Session Tracker'!$E$5:$E$149,MATCH(SMALL('Session Tracker'!$M$5:$M$149,$A9),'Session Tracker'!$M$5:$M$149,0)),"")) | D9: =IF($A9="","",IFERROR(INDEX('Session Tracker'!$D$5:$D$149,MATCH(SMALL('Session Tracker'!$M$5:$M$149,$A9),'Session Tracker'!$M$5:$M$149,0)),"")) | E9: =IF($A9="","",IFERROR(INDEX('Session Tracker'!$H$5:$H$149,MATCH(SMALL('Session Tracker'!$M$5:$M$149,$A9),'Session Tracker'!$M$5:$M$149,0)),"")&"") | G9: =IF($A9="","",IFERROR(INDEX('Session Tracker'!$A$5:$A$149,MATCH(SMALL('Session Tracker'!$M$5:$M$149,$A9),'Session Tracker'!$M$5:$M$149,0)),"")) | J9: =IF($A9="","",IFERROR(INDEX('Session Tracker'!$J$5:$J$149,MATCH(SMALL('Session Tracker'!$M$5:$M$149,$A9),'Session Tracker'!$M$5:$M$149,0)),"")) | K9: =IF($A9="","",IFERROR(INDEX('Session Tracker'!$I$5:$I$149,MATCH(SMALL('Session Tracker'!$M$5:$M$149,$A9),'Session Tracker'!$M$5:$M$149,0)),"")&"")
A10: =IF(3<=COUNT('Session Tracker'!$M$5:$M$149),3,"") | B10: =IF($A10="","",IF(IFERROR(INDEX('Session Tracker'!$G$5:$G$149,MATCH(SMALL('Session Tracker'!$M$5:$M$149,$A10),'Session Tracker'!$M$5:$M$149,0)),"")="","Day not set",IFERROR(INDEX('Session Tracker'!$G$5:$G$149,MATCH(SMALL('Session Tracker'!$M$5:$M$149,$A10),'Session Tracker'!$M$5:$M$149,0)),"")&IF($C$3="",""," "&TEXT($C$3+MATCH(IFERROR(INDEX('Session Tracker'!$G$5:$G$149,MATCH(SMALL('Session Tracker'!$M$5:$M$149,$A10),'Session Tracker'!$M$5:$M$149,0)),""),{"Mon","Tue","Wed","Thu","Fri"},0)-1,"dd-mmm")))) | C10: =IF($A10="","",IFERROR(INDEX('Session Tracker'!$E$5:$E$149,MATCH(SMALL('Session Tracker'!$M$5:$M$149,$A10),'Session Tracker'!$M$5:$M$149,0)),"")) | D10: =IF($A10="","",IFERROR(INDEX('Session Tracker'!$D$5:$D$149,MATCH(SMALL('Session Tracker'!$M$5:$M$149,$A10),'Session Tracker'!$M$5:$M$149,0)),"")) | E10: =IF($A10="","",IFERROR(INDEX('Session Tracker'!$H$5:$H$149,MATCH(SMALL('Session Tracker'!$M$5:$M$149,$A10),'Session Tracker'!$M$5:$M$149,0)),"")&"") | G10: =IF($A10="","",IFERROR(INDEX('Session Tracker'!$A$5:$A$149,MATCH(SMALL('Session Tracker'!$M$5:$M$149,$A10),'Session Tracker'!$M$5:$M$149,0)),"")) | J10: =IF($A10="","",IFERROR(INDEX('Session Tracker'!$J$5:$J$149,MATCH(SMALL('Session Tracker'!$M$5:$M$149,$A10),'Session Tracker'!$M$5:$M$149,0)),"")) | K10: =IF($A10="","",IFERROR(INDEX('Session Tracker'!$I$5:$I$149,MATCH(SMALL('Session Tracker'!$M$5:$M$149,$A10),'Session Tracker'!$M$5:$M$149,0)),"")&"")
A11: =IF(4<=COUNT('Session Tracker'!$M$5:$M$149),4,"") | B11: =IF($A11="","",IF(IFERROR(INDEX('Session Tracker'!$G$5:$G$149,MATCH(SMALL('Session Tracker'!$M$5:$M$149,$A11),'Session Tracker'!$M$5:$M$149,0)),"")="","Day not set",IFERROR(INDEX('Session Tracker'!$G$5:$G$149,MATCH(SMALL('Session Tracker'!$M$5:$M$149,$A11),'Session Tracker'!$M$5:$M$149,0)),"")&IF($C$3="",""," "&TEXT($C$3+MATCH(IFERROR(INDEX('Session Tracker'!$G$5:$G$149,MATCH(SMALL('Session Tracker'!$M$5:$M$149,$A11),'Session Tracker'!$M$5:$M$149,0)),""),{"Mon","Tue","Wed","Thu","Fri"},0)-1,"dd-mmm")))) | C11: =IF($A11="","",IFERROR(INDEX('Session Tracker'!$E$5:$E$149,MATCH(SMALL('Session Tracker'!$M$5:$M$149,$A11),'Session Tracker'!$M$5:$M$149,0)),"")) | D11: =IF($A11="","",IFERROR(INDEX('Session Tracker'!$D$5:$D$149,MATCH(SMALL('Session Tracker'!$M$5:$M$149,$A11),'Session Tracker'!$M$5:$M$149,0)),"")) | E11: =IF($A11="","",IFERROR(INDEX('Session Tracker'!$H$5:$H$149,MATCH(SMALL('Session Tracker'!$M$5:$M$149,$A11),'Session Tracker'!$M$5:$M$149,0)),"")&"") | G11: =IF($A11="","",IFERROR(INDEX('Session Tracker'!$A$5:$A$149,MATCH(SMALL('Session Tracker'!$M$5:$M$149,$A11),'Session Tracker'!$M$5:$M$149,0)),"")) | J11: =IF($A11="","",IFERROR(INDEX('Session Tracker'!$J$5:$J$149,MATCH(SMALL('Session Tracker'!$M$5:$M$149,$A11),'Session Tracker'!$M$5:$M$149,0)),"")) | K11: =IF($A11="","",IFERROR(INDEX('Session Tracker'!$I$5:$I$149,MATCH(SMALL('Session Tracker'!$M$5:$M$149,$A11),'Session Tracker'!$M$5:$M$149,0)),"")&"")
A12: =IF(5<=COUNT('Session Tracker'!$M$5:$M$149),5,"") | B12: =IF($A12="","",IF(IFERROR(INDEX('Session Tracker'!$G$5:$G$149,MATCH(SMALL('Session Tracker'!$M$5:$M$149,$A12),'Session Tracker'!$M$5:$M$149,0)),"")="","Day not set",IFERROR(INDEX('Session Tracker'!$G$5:$G$149,MATCH(SMALL('Session Tracker'!$M$5:$M$149,$A12),'Session Tracker'!$M$5:$M$149,0)),"")&IF($C$3="",""," "&TEXT($C$3+MATCH(IFERROR(INDEX('Session Tracker'!$G$5:$G$149,MATCH(SMALL('Session Tracker'!$M$5:$M$149,$A12),'Session Tracker'!$M$5:$M$149,0)),""),{"Mon","Tue","Wed","Thu","Fri"},0)-1,"dd-mmm")))) | C12: =IF($A12="","",IFERROR(INDEX('Session Tracker'!$E$5:$E$149,MATCH(SMALL('Session Tracker'!$M$5:$M$149,$A12),'Session Tracker'!$M$5:$M$149,0)),"")) | D12: =IF($A12="","",IFERROR(INDEX('Session Tracker'!$D$5:$D$149,MATCH(SMALL('Session Tracker'!$M$5:$M$149,$A12),'Session Tracker'!$M$5:$M$149,0)),"")) | E12: =IF($A12="","",IFERROR(INDEX('Session Tracker'!$H$5:$H$149,MATCH(SMALL('Session Tracker'!$M$5:$M$149,$A12),'Session Tracker'!$M$5:$M$149,0)),"")&"") | G12: =IF($A12="","",IFERROR(INDEX('Session Tracker'!$A$5:$A$149,MATCH(SMALL('Session Tracker'!$M$5:$M$149,$A12),'Session Tracker'!$M$5:$M$149,0)),"")) | J12: =IF($A12="","",IFERROR(INDEX('Session Tracker'!$J$5:$J$149,MATCH(SMALL('Session Tracker'!$M$5:$M$149,$A12),'Session Tracker'!$M$5:$M$149,0)),"")) | K12: =IF($A12="","",IFERROR(INDEX('Session Tracker'!$I$5:$I$149,MATCH(SMALL('Session Tracker'!$M$5:$M$149,$A12),'Session Tracker'!$M$5:$M$149,0)),"")&"")
A13: =IF(6<=COUNT('Session Tracker'!$M$5:$M$149),6,"") | B13: =IF($A13="","",IF(IFERROR(INDEX('Session Tracker'!$G$5:$G$149,MATCH(SMALL('Session Tracker'!$M$5:$M$149,$A13),'Session Tracker'!$M$5:$M$149,0)),"")="","Day not set",IFERROR(INDEX('Session Tracker'!$G$5:$G$149,MATCH(SMALL('Session Tracker'!$M$5:$M$149,$A13),'Session Tracker'!$M$5:$M$149,0)),"")&IF($C$3="",""," "&TEXT($C$3+MATCH(IFERROR(INDEX('Session Tracker'!$G$5:$G$149,MATCH(SMALL('Session Tracker'!$M$5:$M$149,$A13),'Session Tracker'!$M$5:$M$149,0)),""),{"Mon","Tue","Wed","Thu","Fri"},0)-1,"dd-mmm")))) | C13: =IF($A13="","",IFERROR(INDEX('Session Tracker'!$E$5:$E$149,MATCH(SMALL('Session Tracker'!$M$5:$M$149,$A13),'Session Tracker'!$M$5:$M$149,0)),"")) | D13: =IF($A13="","",IFERROR(INDEX('Session Tracker'!$D$5:$D$149,MATCH(SMALL('Session Tracker'!$M$5:$M$149,$A13),'Session Tracker'!$M$5:$M$149,0)),"")) | E13: =IF($A13="","",IFERROR(INDEX('Session Tracker'!$H$5:$H$149,MATCH(SMALL('Session Tracker'!$M$5:$M$149,$A13),'Session Tracker'!$M$5:$M$149,0)),"")&"") | G13: =IF($A13="","",IFERROR(INDEX('Session Tracker'!$A$5:$A$149,MATCH(SMALL('Session Tracker'!$M$5:$M$149,$A13),'Session Tracker'!$M$5:$M$149,0)),"")) | J13: =IF($A13="","",IFERROR(INDEX('Session Tracker'!$J$5:$J$149,MATCH(SMALL('Session Tracker'!$M$5:$M$149,$A13),'Session Tracker'!$M$5:$M$149,0)),"")) | K13: =IF($A13="","",IFERROR(INDEX('Session Tracker'!$I$5:$I$149,MATCH(SMALL('Session Tracker'!$M$5:$M$149,$A13),'Session Tracker'!$M$5:$M$149,0)),"")&"")
A14: =IF(7<=COUNT('Session Tracker'!$M$5:$M$149),7,"") | B14: =IF($A14="","",IF(IFERROR(INDEX('Session Tracker'!$G$5:$G$149,MATCH(SMALL('Session Tracker'!$M$5:$M$149,$A14),'Session Tracker'!$M$5:$M$149,0)),"")="","Day not set",IFERROR(INDEX('Session Tracker'!$G$5:$G$149,MATCH(SMALL('Session Tracker'!$M$5:$M$149,$A14),'Session Tracker'!$M$5:$M$149,0)),"")&IF($C$3="",""," "&TEXT($C$3+MATCH(IFERROR(INDEX('Session Tracker'!$G$5:$G$149,MATCH(SMALL('Session Tracker'!$M$5:$M$149,$A14),'Session Tracker'!$M$5:$M$149,0)),""),{"Mon","Tue","Wed","Thu","Fri"},0)-1,"dd-mmm")))) | C14: =IF($A14="","",IFERROR(INDEX('Session Tracker'!$E$5:$E$149,MATCH(SMALL('Session Tracker'!$M$5:$M$149,$A14),'Session Tracker'!$M$5:$M$149,0)),"")) | D14: =IF($A14="","",IFERROR(INDEX('Session Tracker'!$D$5:$D$149,MATCH(SMALL('Session Tracker'!$M$5:$M$149,$A14),'Session Tracker'!$M$5:$M$149,0)),"")) | E14: =IF($A14="","",IFERROR(INDEX('Session Tracker'!$H$5:$H$149,MATCH(SMALL('Session Tracker'!$M$5:$M$149,$A14),'Session Tracker'!$M$5:$M$149,0)),"")&"") | G14: =IF($A14="","",IFERROR(INDEX('Session Tracker'!$A$5:$A$149,MATCH(SMALL('Session Tracker'!$M$5:$M$149,$A14),'Session Tracker'!$M$5:$M$149,0)),"")) | J14: =IF($A14="","",IFERROR(INDEX('Session Tracker'!$J$5:$J$149,MATCH(SMALL('Session Tracker'!$M$5:$M$149,$A14),'Session Tracker'!$M$5:$M$149,0)),"")) | K14: =IF($A14="","",IFERROR(INDEX('Session Tracker'!$I$5:$I$149,MATCH(SMALL('Session Tracker'!$M$5:$M$149,$A14),'Session Tracker'!$M$5:$M$149,0)),"")&"")
A15: =IF(8<=COUNT('Session Tracker'!$M$5:$M$149),8,"") | B15: =IF($A15="","",IF(IFERROR(INDEX('Session Tracker'!$G$5:$G$149,MATCH(SMALL('Session Tracker'!$M$5:$M$149,$A15),'Session Tracker'!$M$5:$M$149,0)),"")="","Day not set",IFERROR(INDEX('Session Tracker'!$G$5:$G$149,MATCH(SMALL('Session Tracker'!$M$5:$M$149,$A15),'Session Tracker'!$M$5:$M$149,0)),"")&IF($C$3="",""," "&TEXT($C$3+MATCH(IFERROR(INDEX('Session Tracker'!$G$5:$G$149,MATCH(SMALL('Session Tracker'!$M$5:$M$149,$A15),'Session Tracker'!$M$5:$M$149,0)),""),{"Mon","Tue","Wed","Thu","Fri"},0)-1,"dd-mmm")))) | C15: =IF($A15="","",IFERROR(INDEX('Session Tracker'!$E$5:$E$149,MATCH(SMALL('Session Tracker'!$M$5:$M$149,$A15),'Session Tracker'!$M$5:$M$149,0)),"")) | D15: =IF($A15="","",IFERROR(INDEX('Session Tracker'!$D$5:$D$149,MATCH(SMALL('Session Tracker'!$M$5:$M$149,$A15),'Session Tracker'!$M$5:$M$149,0)),"")) | E15: =IF($A15="","",IFERROR(INDEX('Session Tracker'!$H$5:$H$149,MATCH(SMALL('Session Tracker'!$M$5:$M$149,$A15),'Session Tracker'!$M$5:$M$149,0)),"")&"") | G15: =IF($A15="","",IFERROR(INDEX('Session Tracker'!$A$5:$A$149,MATCH(SMALL('Session Tracker'!$M$5:$M$149,$A15),'Session Tracker'!$M$5:$M$149,0)),"")) | J15: =IF($A15="","",IFERROR(INDEX('Session Tracker'!$J$5:$J$149,MATCH(SMALL('Session Tracker'!$M$5:$M$149,$A15),'Session Tracker'!$M$5:$M$149,0)),"")) | K15: =IF($A15="","",IFERROR(INDEX('Session Tracker'!$I$5:$I$149,MATCH(SMALL('Session Tracker'!$M$5:$M$149,$A15),'Session Tracker'!$M$5:$M$149,0)),"")&"")
A16: =IF(9<=COUNT('Session Tracker'!$M$5:$M$149),9,"") | B16: =IF($A16="","",IF(IFERROR(INDEX('Session Tracker'!$G$5:$G$149,MATCH(SMALL('Session Tracker'!$M$5:$M$149,$A16),'Session Tracker'!$M$5:$M$149,0)),"")="","Day not set",IFERROR(INDEX('Session Tracker'!$G$5:$G$149,MATCH(SMALL('Session Tracker'!$M$5:$M$149,$A16),'Session Tracker'!$M$5:$M$149,0)),"")&IF($C$3="",""," "&TEXT($C$3+MATCH(IFERROR(INDEX('Session Tracker'!$G$5:$G$149,MATCH(SMALL('Session Tracker'!$M$5:$M$149,$A16),'Session Tracker'!$M$5:$M$149,0)),""),{"Mon","Tue","Wed","Thu","Fri"},0)-1,"dd-mmm")))) | C16: =IF($A16="","",IFERROR(INDEX('Session Tracker'!$E$5:$E$149,MATCH(SMALL('Session Tracker'!$M$5:$M$149,$A16),'Session Tracker'!$M$5:$M$149,0)),"")) | D16: =IF($A16="","",IFERROR(INDEX('Session Tracker'!$D$5:$D$149,MATCH(SMALL('Session Tracker'!$M$5:$M$149,$A16),'Session Tracker'!$M$5:$M$149,0)),"")) | E16: =IF($A16="","",IFERROR(INDEX('Session Tracker'!$H$5:$H$149,MATCH(SMALL('Session Tracker'!$M$5:$M$149,$A16),'Session Tracker'!$M$5:$M$149,0)),"")&"") | G16: =IF($A16="","",IFERROR(INDEX('Session Tracker'!$A$5:$A$149,MATCH(SMALL('Session Tracker'!$M$5:$M$149,$A16),'Session Tracker'!$M$5:$M$149,0)),"")) | J16: =IF($A16="","",IFERROR(INDEX('Session Tracker'!$J$5:$J$149,MATCH(SMALL('Session Tracker'!$M$5:$M$149,$A16),'Session Tracker'!$M$5:$M$149,0)),"")) | K16: =IF($A16="","",IFERROR(INDEX('Session Tracker'!$I$5:$I$149,MATCH(SMALL('Session Tracker'!$M$5:$M$149,$A16),'Session Tracker'!$M$5:$M$149,0)),"")&"")
A17: =IF(10<=COUNT('Session Tracker'!$M$5:$M$149),10,"") | B17: =IF($A17="","",IF(IFERROR(INDEX('Session Tracker'!$G$5:$G$149,MATCH(SMALL('Session Tracker'!$M$5:$M$149,$A17),'Session Tracker'!$M$5:$M$149,0)),"")="","Day not set",IFERROR(INDEX('Session Tracker'!$G$5:$G$149,MATCH(SMALL('Session Tracker'!$M$5:$M$149,$A17),'Session Tracker'!$M$5:$M$149,0)),"")&IF($C$3="",""," "&TEXT($C$3+MATCH(IFERROR(INDEX('Session Tracker'!$G$5:$G$149,MATCH(SMALL('Session Tracker'!$M$5:$M$149,$A17),'Session Tracker'!$M$5:$M$149,0)),""),{"Mon","Tue","Wed","Thu","Fri"},0)-1,"dd-mmm")))) | C17: =IF($A17="","",IFERROR(INDEX('Session Tracker'!$E$5:$E$149,MATCH(SMALL('Session Tracker'!$M$5:$M$149,$A17),'Session Tracker'!$M$5:$M$149,0)),"")) | D17: =IF($A17="","",IFERROR(INDEX('Session Tracker'!$D$5:$D$149,MATCH(SMALL('Session Tracker'!$M$5:$M$149,$A17),'Session Tracker'!$M$5:$M$149,0)),"")) | E17: =IF($A17="","",IFERROR(INDEX('Session Tracker'!$H$5:$H$149,MATCH(SMALL('Session Tracker'!$M$5:$M$149,$A17),'Session Tracker'!$M$5:$M$149,0)),"")&"") | G17: =IF($A17="","",IFERROR(INDEX('Session Tracker'!$A$5:$A$149,MATCH(SMALL('Session Tracker'!$M$5:$M$149,$A17),'Session Tracker'!$M$5:$M$149,0)),"")) | J17: =IF($A17="","",IFERROR(INDEX('Session Tracker'!$J$5:$J$149,MATCH(SMALL('Session Tracker'!$M$5:$M$149,$A17),'Session Tracker'!$M$5:$M$149,0)),"")) | K17: =IF($A17="","",IFERROR(INDEX('Session Tracker'!$I$5:$I$149,MATCH(SMALL('Session Tracker'!$M$5:$M$149,$A17),'Session Tracker'!$M$5:$M$149,0)),"")&"")
A18: =IF(11<=COUNT('Session Tracker'!$M$5:$M$149),11,"") | B18: =IF($A18="","",IF(IFERROR(INDEX('Session Tracker'!$G$5:$G$149,MATCH(SMALL('Session Tracker'!$M$5:$M$149,$A18),'Session Tracker'!$M$5:$M$149,0)),"")="","Day not set",IFERROR(INDEX('Session Tracker'!$G$5:$G$149,MATCH(SMALL('Session Tracker'!$M$5:$M$149,$A18),'Session Tracker'!$M$5:$M$149,0)),"")&IF($C$3="",""," "&TEXT($C$3+MATCH(IFERROR(INDEX('Session Tracker'!$G$5:$G$149,MATCH(SMALL('Session Tracker'!$M$5:$M$149,$A18),'Session Tracker'!$M$5:$M$149,0)),""),{"Mon","Tue","Wed","Thu","Fri"},0)-1,"dd-mmm")))) | C18: =IF($A18="","",IFERROR(INDEX('Session Tracker'!$E$5:$E$149,MATCH(SMALL('Session Tracker'!$M$5:$M$149,$A18),'Session Tracker'!$M$5:$M$149,0)),"")) | D18: =IF($A18="","",IFERROR(INDEX('Session Tracker'!$D$5:$D$149,MATCH(SMALL('Session Tracker'!$M$5:$M$149,$A18),'Session Tracker'!$M$5:$M$149,0)),"")) | E18: =IF($A18="","",IFERROR(INDEX('Session Tracker'!$H$5:$H$149,MATCH(SMALL('Session Tracker'!$M$5:$M$149,$A18),'Session Tracker'!$M$5:$M$149,0)),"")&"") | G18: =IF($A18="","",IFERROR(INDEX('Session Tracker'!$A$5:$A$149,MATCH(SMALL('Session Tracker'!$M$5:$M$149,$A18),'Session Tracker'!$M$5:$M$149,0)),"")) | J18: =IF($A18="","",IFERROR(INDEX('Session Tracker'!$J$5:$J$149,MATCH(SMALL('Session Tracker'!$M$5:$M$149,$A18),'Session Tracker'!$M$5:$M$149,0)),"")) | K18: =IF($A18="","",IFERROR(INDEX('Session Tracker'!$I$5:$I$149,MATCH(SMALL('Session Tracker'!$M$5:$M$149,$A18),'Session Tracker'!$M$5:$M$149,0)),"")&"")
A19: =IF(12<=COUNT('Session Tracker'!$M$5:$M$149),12,"") | B19: =IF($A19="","",IF(IFERROR(INDEX('Session Tracker'!$G$5:$G$149,MATCH(SMALL('Session Tracker'!$M$5:$M$149,$A19),'Session Tracker'!$M$5:$M$149,0)),"")="","Day not set",IFERROR(INDEX('Session Tracker'!$G$5:$G$149,MATCH(SMALL('Session Tracker'!$M$5:$M$149,$A19),'Session Tracker'!$M$5:$M$149,0)),"")&IF($C$3="",""," "&TEXT($C$3+MATCH(IFERROR(INDEX('Session Tracker'!$G$5:$G$149,MATCH(SMALL('Session Tracker'!$M$5:$M$149,$A19),'Session Tracker'!$M$5:$M$149,0)),""),{"Mon","Tue","Wed","Thu","Fri"},0)-1,"dd-mmm")))) | C19: =IF($A19="","",IFERROR(INDEX('Session Tracker'!$E$5:$E$149,MATCH(SMALL('Session Tracker'!$M$5:$M$149,$A19),'Session Tracker'!$M$5:$M$149,0)),"")) | D19: =IF($A19="","",IFERROR(INDEX('Session Tracker'!$D$5:$D$149,MATCH(SMALL('Session Tracker'!$M$5:$M$149,$A19),'Session Tracker'!$M$5:$M$149,0)),"")) | E19: =IF($A19="","",IFERROR(INDEX('Session Tracker'!$H$5:$H$149,MATCH(SMALL('Session Tracker'!$M$5:$M$149,$A19),'Session Tracker'!$M$5:$M$149,0)),"")&"") | G19: =IF($A19="","",IFERROR(INDEX('Session Tracker'!$A$5:$A$149,MATCH(SMALL('Session Tracker'!$M$5:$M$149,$A19),'Session Tracker'!$M$5:$M$149,0)),"")) | J19: =IF($A19="","",IFERROR(INDEX('Session Tracker'!$J$5:$J$149,MATCH(SMALL('Session Tracker'!$M$5:$M$149,$A19),'Session Tracker'!$M$5:$M$149,0)),"")) | K19: =IF($A19="","",IFERROR(INDEX('Session Tracker'!$I$5:$I$149,MATCH(SMALL('Session Tracker'!$M$5:$M$149,$A19),'Session Tracker'!$M$5:$M$149,0)),"")&"")
A21: B. Hardware to issue, day by day | E21: All sessions on the same day are added together. Make one kit set per day.
B22: Category | C22: Component | D22: Type | E22: Qty | K22: Packed ✓ | L22: Returned ✓ | M22: Notes
B23: =IF($O23="","",IF($O23=0,INDEX(DayLines!$D$3:$D$608,MATCH(SMALL(DayLines!$C$3:$C$608,1),DayLines!$C$3:$C$608,0)),IF($O23=999,"",INDEX(DayLines!$E$3:$E$608,MATCH(SMALL(DayLines!$C$3:$C$608,1),DayLines!$C$3:$C$608,0))))) | C23: =IF($O23="","",IF($O23=0,INDEX(DayLines!$E$3:$E$608,MATCH(SMALL(DayLines!$C$3:$C$608,1),DayLines!$C$3:$C$608,0)),IF($O23=999,"",INDEX(DayLines!$D$3:$D$608,MATCH(SMALL(DayLines!$C$3:$C$608,1),DayLines!$C$3:$C$608,0))))) | D23: =IF(OR($O23="",$O23=0,$O23=999),"",INDEX(DayLines!$F$3:$F$608,MATCH(SMALL(DayLines!$C$3:$C$608,1),DayLines!$C$3:$C$608,0))) | E23: =IF(OR($O23="",$O23=0,$O23=999),"",INDEX(DayLines!$G$3:$G$608,MATCH(SMALL(DayLines!$C$3:$C$608,1),DayLines!$C$3:$C$608,0))) | O23: =IFERROR(MOD(SMALL(DayLines!$C$3:$C$608,1),1000),"")
B24: =IF($O24="","",IF($O24=0,INDEX(DayLines!$D$3:$D$608,MATCH(SMALL(DayLines!$C$3:$C$608,2),DayLines!$C$3:$C$608,0)),IF($O24=999,"",INDEX(DayLines!$E$3:$E$608,MATCH(SMALL(DayLines!$C$3:$C$608,2),DayLines!$C$3:$C$608,0))))) | C24: =IF($O24="","",IF($O24=0,INDEX(DayLines!$E$3:$E$608,MATCH(SMALL(DayLines!$C$3:$C$608,2),DayLines!$C$3:$C$608,0)),IF($O24=999,"",INDEX(DayLines!$D$3:$D$608,MATCH(SMALL(DayLines!$C$3:$C$608,2),DayLines!$C$3:$C$608,0))))) | D24: =IF(OR($O24="",$O24=0,$O24=999),"",INDEX(DayLines!$F$3:$F$608,MATCH(SMALL(DayLines!$C$3:$C$608,2),DayLines!$C$3:$C$608,0))) | E24: =IF(OR($O24="",$O24=0,$O24=999),"",INDEX(DayLines!$G$3:$G$608,MATCH(SMALL(DayLines!$C$3:$C$608,2),DayLines!$C$3:$C$608,0))) | O24: =IFERROR(MOD(SMALL(DayLines!$C$3:$C$608,2),1000),"")
B25: =IF($O25="","",IF($O25=0,INDEX(DayLines!$D$3:$D$608,MATCH(SMALL(DayLines!$C$3:$C$608,3),DayLines!$C$3:$C$608,0)),IF($O25=999,"",INDEX(DayLines!$E$3:$E$608,MATCH(SMALL(DayLines!$C$3:$C$608,3),DayLines!$C$3:$C$608,0))))) | C25: =IF($O25="","",IF($O25=0,INDEX(DayLines!$E$3:$E$608,MATCH(SMALL(DayLines!$C$3:$C$608,3),DayLines!$C$3:$C$608,0)),IF($O25=999,"",INDEX(DayLines!$D$3:$D$608,MATCH(SMALL(DayLines!$C$3:$C$608,3),DayLines!$C$3:$C$608,0))))) | D25: =IF(OR($O25="",$O25=0,$O25=999),"",INDEX(DayLines!$F$3:$F$608,MATCH(SMALL(DayLines!$C$3:$C$608,3),DayLines!$C$3:$C$608,0))) | E25: =IF(OR($O25="",$O25=0,$O25=999),"",INDEX(DayLines!$G$3:$G$608,MATCH(SMALL(DayLines!$C$3:$C$608,3),DayLines!$C$3:$C$608,0))) | O25: =IFERROR(MOD(SMALL(DayLines!$C$3:$C$608,3),1000),"")
B26: =IF($O26="","",IF($O26=0,INDEX(DayLines!$D$3:$D$608,MATCH(SMALL(DayLines!$C$3:$C$608,4),DayLines!$C$3:$C$608,0)),IF($O26=999,"",INDEX(DayLines!$E$3:$E$608,MATCH(SMALL(DayLines!$C$3:$C$608,4),DayLines!$C$3:$C$608,0))))) | C26: =IF($O26="","",IF($O26=0,INDEX(DayLines!$E$3:$E$608,MATCH(SMALL(DayLines!$C$3:$C$608,4),DayLines!$C$3:$C$608,0)),IF($O26=999,"",INDEX(DayLines!$D$3:$D$608,MATCH(SMALL(DayLines!$C$3:$C$608,4),DayLines!$C$3:$C$608,0))))) | D26: =IF(OR($O26="",$O26=0,$O26=999),"",INDEX(DayLines!$F$3:$F$608,MATCH(SMALL(DayLines!$C$3:$C$608,4),DayLines!$C$3:$C$608,0))) | E26: =IF(OR($O26="",$O26=0,$O26=999),"",INDEX(DayLines!$G$3:$G$608,MATCH(SMALL(DayLines!$C$3:$C$608,4),DayLines!$C$3:$C$608,0))) | O26: =IFERROR(MOD(SMALL(DayLines!$C$3:$C$608,4),1000),"")
B27: =IF($O27="","",IF($O27=0,INDEX(DayLines!$D$3:$D$608,MATCH(SMALL(DayLines!$C$3:$C$608,5),DayLines!$C$3:$C$608,0)),IF($O27=999,"",INDEX(DayLines!$E$3:$E$608,MATCH(SMALL(DayLines!$C$3:$C$608,5),DayLines!$C$3:$C$608,0))))) | C27: =IF($O27="","",IF($O27=0,INDEX(DayLines!$E$3:$E$608,MATCH(SMALL(DayLines!$C$3:$C$608,5),DayLines!$C$3:$C$608,0)),IF($O27=999,"",INDEX(DayLines!$D$3:$D$608,MATCH(SMALL(DayLines!$C$3:$C$608,5),DayLines!$C$3:$C$608,0))))) | D27: =IF(OR($O27="",$O27=0,$O27=999),"",INDEX(DayLines!$F$3:$F$608,MATCH(SMALL(DayLines!$C$3:$C$608,5),DayLines!$C$3:$C$608,0))) | E27: =IF(OR($O27="",$O27=0,$O27=999),"",INDEX(DayLines!$G$3:$G$608,MATCH(SMALL(DayLines!$C$3:$C$608,5),DayLines!$C$3:$C$608,0))) | O27: =IFERROR(MOD(SMALL(DayLines!$C$3:$C$608,5),1000),"")
B28: =IF($O28="","",IF($O28=0,INDEX(DayLines!$D$3:$D$608,MATCH(SMALL(DayLines!$C$3:$C$608,6),DayLines!$C$3:$C$608,0)),IF($O28=999,"",INDEX(DayLines!$E$3:$E$608,MATCH(SMALL(DayLines!$C$3:$C$608,6),DayLines!$C$3:$C$608,0))))) | C28: =IF($O28="","",IF($O28=0,INDEX(DayLines!$E$3:$E$608,MATCH(SMALL(DayLines!$C$3:$C$608,6),DayLines!$C$3:$C$608,0)),IF($O28=999,"",INDEX(DayLines!$D$3:$D$608,MATCH(SMALL(DayLines!$C$3:$C$608,6),DayLines!$C$3:$C$608,0))))) | D28: =IF(OR($O28="",$O28=0,$O28=999),"",INDEX(DayLines!$F$3:$F$608,MATCH(SMALL(DayLines!$C$3:$C$608,6),DayLines!$C$3:$C$608,0))) | E28: =IF(OR($O28="",$O28=0,$O28=999),"",INDEX(DayLines!$G$3:$G$608,MATCH(SMALL(DayLines!$C$3:$C$608,6),DayLines!$C$3:$C$608,0))) | O28: =IFERROR(MOD(SMALL(DayLines!$C$3:$C$608,6),1000),"")
B29: =IF($O29="","",IF($O29=0,INDEX(DayLines!$D$3:$D$608,MATCH(SMALL(DayLines!$C$3:$C$608,7),DayLines!$C$3:$C$608,0)),IF($O29=999,"",INDEX(DayLines!$E$3:$E$608,MATCH(SMALL(DayLines!$C$3:$C$608,7),DayLines!$C$3:$C$608,0))))) | C29: =IF($O29="","",IF($O29=0,INDEX(DayLines!$E$3:$E$608,MATCH(SMALL(DayLines!$C$3:$C$608,7),DayLines!$C$3:$C$608,0)),IF($O29=999,"",INDEX(DayLines!$D$3:$D$608,MATCH(SMALL(DayLines!$C$3:$C$608,7),DayLines!$C$3:$C$608,0))))) | D29: =IF(OR($O29="",$O29=0,$O29=999),"",INDEX(DayLines!$F$3:$F$608,MATCH(SMALL(DayLines!$C$3:$C$608,7),DayLines!$C$3:$C$608,0))) | E29: =IF(OR($O29="",$O29=0,$O29=999),"",INDEX(DayLines!$G$3:$G$608,MATCH(SMALL(DayLines!$C$3:$C$608,7),DayLines!$C$3:$C$608,0))) | O29: =IFERROR(MOD(SMALL(DayLines!$C$3:$C$608,7),1000),"")
B30: =IF($O30="","",IF($O30=0,INDEX(DayLines!$D$3:$D$608,MATCH(SMALL(DayLines!$C$3:$C$608,8),DayLines!$C$3:$C$608,0)),IF($O30=999,"",INDEX(DayLines!$E$3:$E$608,MATCH(SMALL(DayLines!$C$3:$C$608,8),DayLines!$C$3:$C$608,0))))) | C30: =IF($O30="","",IF($O30=0,INDEX(DayLines!$E$3:$E$608,MATCH(SMALL(DayLines!$C$3:$C$608,8),DayLines!$C$3:$C$608,0)),IF($O30=999,"",INDEX(DayLines!$D$3:$D$608,MATCH(SMALL(DayLines!$C$3:$C$608,8),DayLines!$C$3:$C$608,0))))) | D30: =IF(OR($O30="",$O30=0,$O30=999),"",INDEX(DayLines!$F$3:$F$608,MATCH(SMALL(DayLines!$C$3:$C$608,8),DayLines!$C$3:$C$608,0))) | E30: =IF(OR($O30="",$O30=0,$O30=999),"",INDEX(DayLines!$G$3:$G$608,MATCH(SMALL(DayLines!$C$3:$C$608,8),DayLines!$C$3:$C$608,0))) | O30: =IFERROR(MOD(SMALL(DayLines!$C$3:$C$608,8),1000),"")
B31: =IF($O31="","",IF($O31=0,INDEX(DayLines!$D$3:$D$608,MATCH(SMALL(DayLines!$C$3:$C$608,9),DayLines!$C$3:$C$608,0)),IF($O31=999,"",INDEX(DayLines!$E$3:$E$608,MATCH(SMALL(DayLines!$C$3:$C$608,9),DayLines!$C$3:$C$608,0))))) | C31: =IF($O31="","",IF($O31=0,INDEX(DayLines!$E$3:$E$608,MATCH(SMALL(DayLines!$C$3:$C$608,9),DayLines!$C$3:$C$608,0)),IF($O31=999,"",INDEX(DayLines!$D$3:$D$608,MATCH(SMALL(DayLines!$C$3:$C$608,9),DayLines!$C$3:$C$608,0))))) | D31: =IF(OR($O31="",$O31=0,$O31=999),"",INDEX(DayLines!$F$3:$F$608,MATCH(SMALL(DayLines!$C$3:$C$608,9),DayLines!$C$3:$C$608,0))) | E31: =IF(OR($O31="",$O31=0,$O31=999),"",INDEX(DayLines!$G$3:$G$608,MATCH(SMALL(DayLines!$C$3:$C$608,9),DayLines!$C$3:$C$608,0))) | O31: =IFERROR(MOD(SMALL(DayLines!$C$3:$C$608,9),1000),"")
B32: =IF($O32="","",IF($O32=0,INDEX(DayLines!$D$3:$D$608,MATCH(SMALL(DayLines!$C$3:$C$608,10),DayLines!$C$3:$C$608,0)),IF($O32=999,"",INDEX(DayLines!$E$3:$E$608,MATCH(SMALL(DayLines!$C$3:$C$608,10),DayLines!$C$3:$C$608,0))))) | C32: =IF($O32="","",IF($O32=0,INDEX(DayLines!$E$3:$E$608,MATCH(SMALL(DayLines!$C$3:$C$608,10),DayLines!$C$3:$C$608,0)),IF($O32=999,"",INDEX(DayLines!$D$3:$D$608,MATCH(SMALL(DayLines!$C$3:$C$608,10),DayLines!$C$3:$C$608,0))))) | D32: =IF(OR($O32="",$O32=0,$O32=999),"",INDEX(DayLines!$F$3:$F$608,MATCH(SMALL(DayLines!$C$3:$C$608,10),DayLines!$C$3:$C$608,0))) | E32: =IF(OR($O32="",$O32=0,$O32=999),"",INDEX(DayLines!$G$3:$G$608,MATCH(SMALL(DayLines!$C$3:$C$608,10),DayLines!$C$3:$C$608,0))) | O32: =IFERROR(MOD(SMALL(DayLines!$C$3:$C$608,10),1000),"")
B33: =IF($O33="","",IF($O33=0,INDEX(DayLines!$D$3:$D$608,MATCH(SMALL(DayLines!$C$3:$C$608,11),DayLines!$C$3:$C$608,0)),IF($O33=999,"",INDEX(DayLines!$E$3:$E$608,MATCH(SMALL(DayLines!$C$3:$C$608,11),DayLines!$C$3:$C$608,0))))) | C33: =IF($O33="","",IF($O33=0,INDEX(DayLines!$E$3:$E$608,MATCH(SMALL(DayLines!$C$3:$C$608,11),DayLines!$C$3:$C$608,0)),IF($O33=999,"",INDEX(DayLines!$D$3:$D$608,MATCH(SMALL(DayLines!$C$3:$C$608,11),DayLines!$C$3:$C$608,0))))) | D33: =IF(OR($O33="",$O33=0,$O33=999),"",INDEX(DayLines!$F$3:$F$608,MATCH(SMALL(DayLines!$C$3:$C$608,11),DayLines!$C$3:$C$608,0))) | E33: =IF(OR($O33="",$O33=0,$O33=999),"",INDEX(DayLines!$G$3:$G$608,MATCH(SMALL(DayLines!$C$3:$C$608,11),DayLines!$C$3:$C$608,0))) | O33: =IFERROR(MOD(SMALL(DayLines!$C$3:$C$608,11),1000),"")
B34: =IF($O34="","",IF($O34=0,INDEX(DayLines!$D$3:$D$608,MATCH(SMALL(DayLines!$C$3:$C$608,12),DayLines!$C$3:$C$608,0)),IF($O34=999,"",INDEX(DayLines!$E$3:$E$608,MATCH(SMALL(DayLines!$C$3:$C$608,12),DayLines!$C$3:$C$608,0))))) | C34: =IF($O34="","",IF($O34=0,INDEX(DayLines!$E$3:$E$608,MATCH(SMALL(DayLines!$C$3:$C$608,12),DayLines!$C$3:$C$608,0)),IF($O34=999,"",INDEX(DayLines!$D$3:$D$608,MATCH(SMALL(DayLines!$C$3:$C$608,12),DayLines!$C$3:$C$608,0))))) | D34: =IF(OR($O34="",$O34=0,$O34=999),"",INDEX(DayLines!$F$3:$F$608,MATCH(SMALL(DayLines!$C$3:$C$608,12),DayLines!$C$3:$C$608,0))) | E34: =IF(OR($O34="",$O34=0,$O34=999),"",INDEX(DayLines!$G$3:$G$608,MATCH(SMALL(DayLines!$C$3:$C$608,12),DayLines!$C$3:$C$608,0))) | O34: =IFERROR(MOD(SMALL(DayLines!$C$3:$C$608,12),1000),"")
B35: =IF($O35="","",IF($O35=0,INDEX(DayLines!$D$3:$D$608,MATCH(SMALL(DayLines!$C$3:$C$608,13),DayLines!$C$3:$C$608,0)),IF($O35=999,"",INDEX(DayLines!$E$3:$E$608,MATCH(SMALL(DayLines!$C$3:$C$608,13),DayLines!$C$3:$C$608,0))))) | C35: =IF($O35="","",IF($O35=0,INDEX(DayLines!$E$3:$E$608,MATCH(SMALL(DayLines!$C$3:$C$608,13),DayLines!$C$3:$C$608,0)),IF($O35=999,"",INDEX(DayLines!$D$3:$D$608,MATCH(SMALL(DayLines!$C$3:$C$608,13),DayLines!$C$3:$C$608,0))))) | D35: =IF(OR($O35="",$O35=0,$O35=999),"",INDEX(DayLines!$F$3:$F$608,MATCH(SMALL(DayLines!$C$3:$C$608,13),DayLines!$C$3:$C$608,0))) | E35: =IF(OR($O35="",$O35=0,$O35=999),"",INDEX(DayLines!$G$3:$G$608,MATCH(SMALL(DayLines!$C$3:$C$608,13),DayLines!$C$3:$C$608,0))) | O35: =IFERROR(MOD(SMALL(DayLines!$C$3:$C$608,13),1000),"")
B36: =IF($O36="","",IF($O36=0,INDEX(DayLines!$D$3:$D$608,MATCH(SMALL(DayLines!$C$3:$C$608,14),DayLines!$C$3:$C$608,0)),IF($O36=999,"",INDEX(DayLines!$E$3:$E$608,MATCH(SMALL(DayLines!$C$3:$C$608,14),DayLines!$C$3:$C$608,0))))) | C36: =IF($O36="","",IF($O36=0,INDEX(DayLines!$E$3:$E$608,MATCH(SMALL(DayLines!$C$3:$C$608,14),DayLines!$C$3:$C$608,0)),IF($O36=999,"",INDEX(DayLines!$D$3:$D$608,MATCH(SMALL(DayLines!$C$3:$C$608,14),DayLines!$C$3:$C$608,0))))) | D36: =IF(OR($O36="",$O36=0,$O36=999),"",INDEX(DayLines!$F$3:$F$608,MATCH(SMALL(DayLines!$C$3:$C$608,14),DayLines!$C$3:$C$608,0))) | E36: =IF(OR($O36="",$O36=0,$O36=999),"",INDEX(DayLines!$G$3:$G$608,MATCH(SMALL(DayLines!$C$3:$C$608,14),DayLines!$C$3:$C$608,0))) | O36: =IFERROR(MOD(SMALL(DayLines!$C$3:$C$608,14),1000),"")
B37: =IF($O37="","",IF($O37=0,INDEX(DayLines!$D$3:$D$608,MATCH(SMALL(DayLines!$C$3:$C$608,15),DayLines!$C$3:$C$608,0)),IF($O37=999,"",INDEX(DayLines!$E$3:$E$608,MATCH(SMALL(DayLines!$C$3:$C$608,15),DayLines!$C$3:$C$608,0))))) | C37: =IF($O37="","",IF($O37=0,INDEX(DayLines!$E$3:$E$608,MATCH(SMALL(DayLines!$C$3:$C$608,15),DayLines!$C$3:$C$608,0)),IF($O37=999,"",INDEX(DayLines!$D$3:$D$608,MATCH(SMALL(DayLines!$C$3:$C$608,15),DayLines!$C$3:$C$608,0))))) | D37: =IF(OR($O37="",$O37=0,$O37=999),"",INDEX(DayLines!$F$3:$F$608,MATCH(SMALL(DayLines!$C$3:$C$608,15),DayLines!$C$3:$C$608,0))) | E37: =IF(OR($O37="",$O37=0,$O37=999),"",INDEX(DayLines!$G$3:$G$608,MATCH(SMALL(DayLines!$C$3:$C$608,15),DayLines!$C$3:$C$608,0))) | O37: =IFERROR(MOD(SMALL(DayLines!$C$3:$C$608,15),1000),"")
B38: =IF($O38="","",IF($O38=0,INDEX(DayLines!$D$3:$D$608,MATCH(SMALL(DayLines!$C$3:$C$608,16),DayLines!$C$3:$C$608,0)),IF($O38=999,"",INDEX(DayLines!$E$3:$E$608,MATCH(SMALL(DayLines!$C$3:$C$608,16),DayLines!$C$3:$C$608,0))))) | C38: =IF($O38="","",IF($O38=0,INDEX(DayLines!$E$3:$E$608,MATCH(SMALL(DayLines!$C$3:$C$608,16),DayLines!$C$3:$C$608,0)),IF($O38=999,"",INDEX(DayLines!$D$3:$D$608,MATCH(SMALL(DayLines!$C$3:$C$608,16),DayLines!$C$3:$C$608,0))))) | D38: =IF(OR($O38="",$O38=0,$O38=999),"",INDEX(DayLines!$F$3:$F$608,MATCH(SMALL(DayLines!$C$3:$C$608,16),DayLines!$C$3:$C$608,0))) | E38: =IF(OR($O38="",$O38=0,$O38=999),"",INDEX(DayLines!$G$3:$G$608,MATCH(SMALL(DayLines!$C$3:$C$608,16),DayLines!$C$3:$C$608,0))) | O38: =IFERROR(MOD(SMALL(DayLines!$C$3:$C$608,16),1000),"")
B39: =IF($O39="","",IF($O39=0,INDEX(DayLines!$D$3:$D$608,MATCH(SMALL(DayLines!$C$3:$C$608,17),DayLines!$C$3:$C$608,0)),IF($O39=999,"",INDEX(DayLines!$E$3:$E$608,MATCH(SMALL(DayLines!$C$3:$C$608,17),DayLines!$C$3:$C$608,0))))) | C39: =IF($O39="","",IF($O39=0,INDEX(DayLines!$E$3:$E$608,MATCH(SMALL(DayLines!$C$3:$C$608,17),DayLines!$C$3:$C$608,0)),IF($O39=999,"",INDEX(DayLines!$D$3:$D$608,MATCH(SMALL(DayLines!$C$3:$C$608,17),DayLines!$C$3:$C$608,0))))) | D39: =IF(OR($O39="",$O39=0,$O39=999),"",INDEX(DayLines!$F$3:$F$608,MATCH(SMALL(DayLines!$C$3:$C$608,17),DayLines!$C$3:$C$608,0))) | E39: =IF(OR($O39="",$O39=0,$O39=999),"",INDEX(DayLines!$G$3:$G$608,MATCH(SMALL(DayLines!$C$3:$C$608,17),DayLines!$C$3:$C$608,0))) | O39: =IFERROR(MOD(SMALL(DayLines!$C$3:$C$608,17),1000),"")
B40: =IF($O40="","",IF($O40=0,INDEX(DayLines!$D$3:$D$608,MATCH(SMALL(DayLines!$C$3:$C$608,18),DayLines!$C$3:$C$608,0)),IF($O40=999,"",INDEX(DayLines!$E$3:$E$608,MATCH(SMALL(DayLines!$C$3:$C$608,18),DayLines!$C$3:$C$608,0))))) | C40: =IF($O40="","",IF($O40=0,INDEX(DayLines!$E$3:$E$608,MATCH(SMALL(DayLines!$C$3:$C$608,18),DayLines!$C$3:$C$608,0)),IF($O40=999,"",INDEX(DayLines!$D$3:$D$608,MATCH(SMALL(DayLines!$C$3:$C$608,18),DayLines!$C$3:$C$608,0))))) | D40: =IF(OR($O40="",$O40=0,$O40=999),"",INDEX(DayLines!$F$3:$F$608,MATCH(SMALL(DayLines!$C$3:$C$608,18),DayLines!$C$3:$C$608,0))) | E40: =IF(OR($O40="",$O40=0,$O40=999),"",INDEX(DayLines!$G$3:$G$608,MATCH(SMALL(DayLines!$C$3:$C$608,18),DayLines!$C$3:$C$608,0))) | O40: =IFERROR(MOD(SMALL(DayLines!$C$3:$C$608,18),1000),"")
B41: =IF($O41="","",IF($O41=0,INDEX(DayLines!$D$3:$D$608,MATCH(SMALL(DayLines!$C$3:$C$608,19),DayLines!$C$3:$C$608,0)),IF($O41=999,"",INDEX(DayLines!$E$3:$E$608,MATCH(SMALL(DayLines!$C$3:$C$608,19),DayLines!$C$3:$C$608,0))))) | C41: =IF($O41="","",IF($O41=0,INDEX(DayLines!$E$3:$E$608,MATCH(SMALL(DayLines!$C$3:$C$608,19),DayLines!$C$3:$C$608,0)),IF($O41=999,"",INDEX(DayLines!$D$3:$D$608,MATCH(SMALL(DayLines!$C$3:$C$608,19),DayLines!$C$3:$C$608,0))))) | D41: =IF(OR($O41="",$O41=0,$O41=999),"",INDEX(DayLines!$F$3:$F$608,MATCH(SMALL(DayLines!$C$3:$C$608,19),DayLines!$C$3:$C$608,0))) | E41: =IF(OR($O41="",$O41=0,$O41=999),"",INDEX(DayLines!$G$3:$G$608,MATCH(SMALL(DayLines!$C$3:$C$608,19),DayLines!$C$3:$C$608,0))) | O41: =IFERROR(MOD(SMALL(DayLines!$C$3:$C$608,19),1000),"")
B42: =IF($O42="","",IF($O42=0,INDEX(DayLines!$D$3:$D$608,MATCH(SMALL(DayLines!$C$3:$C$608,20),DayLines!$C$3:$C$608,0)),IF($O42=999,"",INDEX(DayLines!$E$3:$E$608,MATCH(SMALL(DayLines!$C$3:$C$608,20),DayLines!$C$3:$C$608,0))))) | C42: =IF($O42="","",IF($O42=0,INDEX(DayLines!$E$3:$E$608,MATCH(SMALL(DayLines!$C$3:$C$608,20),DayLines!$C$3:$C$608,0)),IF($O42=999,"",INDEX(DayLines!$D$3:$D$608,MATCH(SMALL(DayLines!$C$3:$C$608,20),DayLines!$C$3:$C$608,0))))) | D42: =IF(OR($O42="",$O42=0,$O42=999),"",INDEX(DayLines!$F$3:$F$608,MATCH(SMALL(DayLines!$C$3:$C$608,20),DayLines!$C$3:$C$608,0))) | E42: =IF(OR($O42="",$O42=0,$O42=999),"",INDEX(DayLines!$G$3:$G$608,MATCH(SMALL(DayLines!$C$3:$C$608,20),DayLines!$C$3:$C$608,0))) | O42: =IFERROR(MOD(SMALL(DayLines!$C$3:$C$608,20),1000),"")
...

Sheet Daily Kit Lists
A1: Robotics & AI Club: Daily Kit Lists
A2: Day by day, then each session in the same format as the kit tabs. Pack one box per session. Fills itself from the Session Tracker (Status = Next week).
A3: ="Week starting: "&IF('This Week''s Hardware'!$C$3="","(set the date on This Week's Hardware)",TEXT('This Week''s Hardware'!$C$3,"dddd dd-mmm-yyyy")) -> Week starting: (set the date on This Week's Hardware)
A5: Code | B5: Category | C5: Component | D5: Qty | E5: Basis | F5: Type | G5: Notes | H5: Total | I5: Packed ✓
A6: =IF(OR($J6=0,AND(ISNUMBER($J6),$J6>0,$J6<99)),INDEX(Lines!$A$3:$A$1590,MATCH(SMALL(Lines!$G$3:$G$1590,1),Lines!$G$3:$G$1590,0)),"") | B6: =IF($J6=-1,INDEX(Lines!$J$3:$J$1590,MATCH(SMALL(Lines!$G$3:$G$1590,1),Lines!$G$3:$G$1590,0)),IF($J6=0,INDEX(Lines!$L$3:$L$1590,MATCH(SMALL(Lines!$G$3:$G$1590,1),Lines!$G$3:$G$1590,0)),IF(AND(ISNUMBER($J6),$J6>0,$J6<99),INDEX(Lines!$N$3:$N$1590,MATCH(SMALL(Lines!$G$3:$G$1590,1),Lines!$G$3:$G$1590,0)),""))) | C6: =IF($J6=0,INDEX(Lines!$K$3:$K$1590,MATCH(SMALL(Lines!$G$3:$G$1590,1),Lines!$G$3:$G$1590,0)),IF(AND(ISNUMBER($J6),$J6>0,$J6<99),INDEX(Lines!$C$3:$C$1590,MATCH(SMALL(Lines!$G$3:$G$1590,1),Lines!$G$3:$G$1590,0)),"")) | D6: =IF(AND(ISNUMBER($J6),$J6>0,$J6<99),INDEX(Lines!$D$3:$D$1590,MATCH(SMALL(Lines!$G$3:$G$1590,1),Lines!$G$3:$G$1590,0)),"") | E6: =IF(AND(ISNUMBER($J6),$J6>0,$J6<99),INDEX(Lines!$E$3:$E$1590,MATCH(SMALL(Lines!$G$3:$G$1590,1),Lines!$G$3:$G$1590,0)),"") | F6: =IF(AND(ISNUMBER($J6),$J6>0,$J6<99),INDEX(Lines!$O$3:$O$1590,MATCH(SMALL(Lines!$G$3:$G$1590,1),Lines!$G$3:$G$1590,0)),"") | G6: =IF($J6=0,INDEX(Lines!$Q$3:$Q$1590,MATCH(SMALL(Lines!$G$3:$G$1590,1),Lines!$G$3:$G$1590,0)),IF(AND(ISNUMBER($J6),$J6>0,$J6<99),INDEX(Lines!$P$3:$P$1590,MATCH(SMALL(Lines!$G$3:$G$1590,1),Lines!$G$3:$G$1590,0)),"")) | H6: =IF($J6=0,INDEX(Lines!$H$3:$H$1590,MATCH(SMALL(Lines!$G$3:$G$1590,1),Lines!$G$3:$G$1590,0))&" groups",IF(AND(ISNUMBER($J6),$J6>0,$J6<99),INDEX(Lines!$I$3:$I$1590,MATCH(SMALL(Lines!$G$3:$G$1590,1),Lines!$G$3:$G$1590,0)),"")) | J6: =IFERROR(IF(MOD(SMALL(Lines!$G$3:$G$1590,1),100000)=0,-1,MOD(SMALL(Lines!$G$3:$G$1590,1),100)),"") | K6: =IF($J6=0,INDEX(Lines!$L$3:$L$1590,MATCH(SMALL(Lines!$G$3:$G$1590,1),Lines!$G$3:$G$1590,0)),"")
A7: =IF(OR($J7=0,AND(ISNUMBER($J7),$J7>0,$J7<99)),INDEX(Lines!$A$3:$A$1590,MATCH(SMALL(Lines!$G$3:$G$1590,2),Lines!$G$3:$G$1590,0)),"") | B7: =IF($J7=-1,INDEX(Lines!$J$3:$J$1590,MATCH(SMALL(Lines!$G$3:$G$1590,2),Lines!$G$3:$G$1590,0)),IF($J7=0,INDEX(Lines!$L$3:$L$1590,MATCH(SMALL(Lines!$G$3:$G$1590,2),Lines!$G$3:$G$1590,0)),IF(AND(ISNUMBER($J7),$J7>0,$J7<99),INDEX(Lines!$N$3:$N$1590,MATCH(SMALL(Lines!$G$3:$G$1590,2),Lines!$G$3:$G$1590,0)),""))) | C7: =IF($J7=0,INDEX(Lines!$K$3:$K$1590,MATCH(SMALL(Lines!$G$3:$G$1590,2),Lines!$G$3:$G$1590,0)),IF(AND(ISNUMBER($J7),$J7>0,$J7<99),INDEX(Lines!$C$3:$C$1590,MATCH(SMALL(Lines!$G$3:$G$1590,2),Lines!$G$3:$G$1590,0)),"")) | D7: =IF(AND(ISNUMBER($J7),$J7>0,$J7<99),INDEX(Lines!$D$3:$D$1590,MATCH(SMALL(Lines!$G$3:$G$1590,2),Lines!$G$3:$G$1590,0)),"") | E7: =IF(AND(ISNUMBER($J7),$J7>0,$J7<99),INDEX(Lines!$E$3:$E$1590,MATCH(SMALL(Lines!$G$3:$G$1590,2),Lines!$G$3:$G$1590,0)),"") | F7: =IF(AND(ISNUMBER($J7),$J7>0,$J7<99),INDEX(Lines!$O$3:$O$1590,MATCH(SMALL(Lines!$G$3:$G$1590,2),Lines!$G$3:$G$1590,0)),"") | G7: =IF($J7=0,INDEX(Lines!$Q$3:$Q$1590,MATCH(SMALL(Lines!$G$3:$G$1590,2),Lines!$G$3:$G$1590,0)),IF(AND(ISNUMBER($J7),$J7>0,$J7<99),INDEX(Lines!$P$3:$P$1590,MATCH(SMALL(Lines!$G$3:$G$1590,2),Lines!$G$3:$G$1590,0)),"")) | H7: =IF($J7=0,INDEX(Lines!$H$3:$H$1590,MATCH(SMALL(Lines!$G$3:$G$1590,2),Lines!$G$3:$G$1590,0))&" groups",IF(AND(ISNUMBER($J7),$J7>0,$J7<99),INDEX(Lines!$I$3:$I$1590,MATCH(SMALL(Lines!$G$3:$G$1590,2),Lines!$G$3:$G$1590,0)),"")) | J7: =IFERROR(IF(MOD(SMALL(Lines!$G$3:$G$1590,2),100000)=0,-1,MOD(SMALL(Lines!$G$3:$G$1590,2),100)),"") | K7: =IF($J7=0,INDEX(Lines!$L$3:$L$1590,MATCH(SMALL(Lines!$G$3:$G$1590,2),Lines!$G$3:$G$1590,0)),"")
A8: =IF(OR($J8=0,AND(ISNUMBER($J8),$J8>0,$J8<99)),INDEX(Lines!$A$3:$A$1590,MATCH(SMALL(Lines!$G$3:$G$1590,3),Lines!$G$3:$G$1590,0)),"") | B8: =IF($J8=-1,INDEX(Lines!$J$3:$J$1590,MATCH(SMALL(Lines!$G$3:$G$1590,3),Lines!$G$3:$G$1590,0)),IF($J8=0,INDEX(Lines!$L$3:$L$1590,MATCH(SMALL(Lines!$G$3:$G$1590,3),Lines!$G$3:$G$1590,0)),IF(AND(ISNUMBER($J8),$J8>0,$J8<99),INDEX(Lines!$N$3:$N$1590,MATCH(SMALL(Lines!$G$3:$G$1590,3),Lines!$G$3:$G$1590,0)),""))) | C8: =IF($J8=0,INDEX(Lines!$K$3:$K$1590,MATCH(SMALL(Lines!$G$3:$G$1590,3),Lines!$G$3:$G$1590,0)),IF(AND(ISNUMBER($J8),$J8>0,$J8<99),INDEX(Lines!$C$3:$C$1590,MATCH(SMALL(Lines!$G$3:$G$1590,3),Lines!$G$3:$G$1590,0)),"")) | D8: =IF(AND(ISNUMBER($J8),$J8>0,$J8<99),INDEX(Lines!$D$3:$D$1590,MATCH(SMALL(Lines!$G$3:$G$1590,3),Lines!$G$3:$G$1590,0)),"") | E8: =IF(AND(ISNUMBER($J8),$J8>0,$J8<99),INDEX(Lines!$E$3:$E$1590,MATCH(SMALL(Lines!$G$3:$G$1590,3),Lines!$G$3:$G$1590,0)),"") | F8: =IF(AND(ISNUMBER($J8),$J8>0,$J8<99),INDEX(Lines!$O$3:$O$1590,MATCH(SMALL(Lines!$G$3:$G$1590,3),Lines!$G$3:$G$1590,0)),"") | G8: =IF($J8=0,INDEX(Lines!$Q$3:$Q$1590,MATCH(SMALL(Lines!$G$3:$G$1590,3),Lines!$G$3:$G$1590,0)),IF(AND(ISNUMBER($J8),$J8>0,$J8<99),INDEX(Lines!$P$3:$P$1590,MATCH(SMALL(Lines!$G$3:$G$1590,3),Lines!$G$3:$G$1590,0)),"")) | H8: =IF($J8=0,INDEX(Lines!$H$3:$H$1590,MATCH(SMALL(Lines!$G$3:$G$1590,3),Lines!$G$3:$G$1590,0))&" groups",IF(AND(ISNUMBER($J8),$J8>0,$J8<99),INDEX(Lines!$I$3:$I$1590,MATCH(SMALL(Lines!$G$3:$G$1590,3),Lines!$G$3:$G$1590,0)),"")) | J8: =IFERROR(IF(MOD(SMALL(Lines!$G$3:$G$1590,3),100000)=0,-1,MOD(SMALL(Lines!$G$3:$G$1590,3),100)),"") | K8: =IF($J8=0,INDEX(Lines!$L$3:$L$1590,MATCH(SMALL(Lines!$G$3:$G$1590,3),Lines!$G$3:$G$1590,0)),"")
A9: =IF(OR($J9=0,AND(ISNUMBER($J9),$J9>0,$J9<99)),INDEX(Lines!$A$3:$A$1590,MATCH(SMALL(Lines!$G$3:$G$1590,4),Lines!$G$3:$G$1590,0)),"") | B9: =IF($J9=-1,INDEX(Lines!$J$3:$J$1590,MATCH(SMALL(Lines!$G$3:$G$1590,4),Lines!$G$3:$G$1590,0)),IF($J9=0,INDEX(Lines!$L$3:$L$1590,MATCH(SMALL(Lines!$G$3:$G$1590,4),Lines!$G$3:$G$1590,0)),IF(AND(ISNUMBER($J9),$J9>0,$J9<99),INDEX(Lines!$N$3:$N$1590,MATCH(SMALL(Lines!$G$3:$G$1590,4),Lines!$G$3:$G$1590,0)),""))) | C9: =IF($J9=0,INDEX(Lines!$K$3:$K$1590,MATCH(SMALL(Lines!$G$3:$G$1590,4),Lines!$G$3:$G$1590,0)),IF(AND(ISNUMBER($J9),$J9>0,$J9<99),INDEX(Lines!$C$3:$C$1590,MATCH(SMALL(Lines!$G$3:$G$1590,4),Lines!$G$3:$G$1590,0)),"")) | D9: =IF(AND(ISNUMBER($J9),$J9>0,$J9<99),INDEX(Lines!$D$3:$D$1590,MATCH(SMALL(Lines!$G$3:$G$1590,4),Lines!$G$3:$G$1590,0)),"") | E9: =IF(AND(ISNUMBER($J9),$J9>0,$J9<99),INDEX(Lines!$E$3:$E$1590,MATCH(SMALL(Lines!$G$3:$G$1590,4),Lines!$G$3:$G$1590,0)),"") | F9: =IF(AND(ISNUMBER($J9),$J9>0,$J9<99),INDEX(Lines!$O$3:$O$1590,MATCH(SMALL(Lines!$G$3:$G$1590,4),Lines!$G$3:$G$1590,0)),"") | G9: =IF($J9=0,INDEX(Lines!$Q$3:$Q$1590,MATCH(SMALL(Lines!$G$3:$G$1590,4),Lines!$G$3:$G$1590,0)),IF(AND(ISNUMBER($J9),$J9>0,$J9<99),INDEX(Lines!$P$3:$P$1590,MATCH(SMALL(Lines!$G$3:$G$1590,4),Lines!$G$3:$G$1590,0)),"")) | H9: =IF($J9=0,INDEX(Lines!$H$3:$H$1590,MATCH(SMALL(Lines!$G$3:$G$1590,4),Lines!$G$3:$G$1590,0))&" groups",IF(AND(ISNUMBER($J9),$J9>0,$J9<99),INDEX(Lines!$I$3:$I$1590,MATCH(SMALL(Lines!$G$3:$G$1590,4),Lines!$G$3:$G$1590,0)),"")) | J9: =IFERROR(IF(MOD(SMALL(Lines!$G$3:$G$1590,4),100000)=0,-1,MOD(SMALL(Lines!$G$3:$G$1590,4),100)),"") | K9: =IF($J9=0,INDEX(Lines!$L$3:$L$1590,MATCH(SMALL(Lines!$G$3:$G$1590,4),Lines!$G$3:$G$1590,0)),"")
A10: =IF(OR($J10=0,AND(ISNUMBER($J10),$J10>0,$J10<99)),INDEX(Lines!$A$3:$A$1590,MATCH(SMALL(Lines!$G$3:$G$1590,5),Lines!$G$3:$G$1590,0)),"") | B10: =IF($J10=-1,INDEX(Lines!$J$3:$J$1590,MATCH(SMALL(Lines!$G$3:$G$1590,5),Lines!$G$3:$G$1590,0)),IF($J10=0,INDEX(Lines!$L$3:$L$1590,MATCH(SMALL(Lines!$G$3:$G$1590,5),Lines!$G$3:$G$1590,0)),IF(AND(ISNUMBER($J10),$J10>0,$J10<99),INDEX(Lines!$N$3:$N$1590,MATCH(SMALL(Lines!$G$3:$G$1590,5),Lines!$G$3:$G$1590,0)),""))) | C10: =IF($J10=0,INDEX(Lines!$K$3:$K$1590,MATCH(SMALL(Lines!$G$3:$G$1590,5),Lines!$G$3:$G$1590,0)),IF(AND(ISNUMBER($J10),$J10>0,$J10<99),INDEX(Lines!$C$3:$C$1590,MATCH(SMALL(Lines!$G$3:$G$1590,5),Lines!$G$3:$G$1590,0)),"")) | D10: =IF(AND(ISNUMBER($J10),$J10>0,$J10<99),INDEX(Lines!$D$3:$D$1590,MATCH(SMALL(Lines!$G$3:$G$1590,5),Lines!$G$3:$G$1590,0)),"") | E10: =IF(AND(ISNUMBER($J10),$J10>0,$J10<99),INDEX(Lines!$E$3:$E$1590,MATCH(SMALL(Lines!$G$3:$G$1590,5),Lines!$G$3:$G$1590,0)),"") | F10: =IF(AND(ISNUMBER($J10),$J10>0,$J10<99),INDEX(Lines!$O$3:$O$1590,MATCH(SMALL(Lines!$G$3:$G$1590,5),Lines!$G$3:$G$1590,0)),"") | G10: =IF($J10=0,INDEX(Lines!$Q$3:$Q$1590,MATCH(SMALL(Lines!$G$3:$G$1590,5),Lines!$G$3:$G$1590,0)),IF(AND(ISNUMBER($J10),$J10>0,$J10<99),INDEX(Lines!$P$3:$P$1590,MATCH(SMALL(Lines!$G$3:$G$1590,5),Lines!$G$3:$G$1590,0)),"")) | H10: =IF($J10=0,INDEX(Lines!$H$3:$H$1590,MATCH(SMALL(Lines!$G$3:$G$1590,5),Lines!$G$3:$G$1590,0))&" groups",IF(AND(ISNUMBER($J10),$J10>0,$J10<99),INDEX(Lines!$I$3:$I$1590,MATCH(SMALL(Lines!$G$3:$G$1590,5),Lines!$G$3:$G$1590,0)),"")) | J10: =IFERROR(IF(MOD(SMALL(Lines!$G$3:$G$1590,5),100000)=0,-1,MOD(SMALL(Lines!$G$3:$G$1590,5),100)),"") | K10: =IF($J10=0,INDEX(Lines!$L$3:$L$1590,MATCH(SMALL(Lines!$G$3:$G$1590,5),Lines!$G$3:$G$1590,0)),"")
A11: =IF(OR($J11=0,AND(ISNUMBER($J11),$J11>0,$J11<99)),INDEX(Lines!$A$3:$A$1590,MATCH(SMALL(Lines!$G$3:$G$1590,6),Lines!$G$3:$G$1590,0)),"") | B11: =IF($J11=-1,INDEX(Lines!$J$3:$J$1590,MATCH(SMALL(Lines!$G$3:$G$1590,6),Lines!$G$3:$G$1590,0)),IF($J11=0,INDEX(Lines!$L$3:$L$1590,MATCH(SMALL(Lines!$G$3:$G$1590,6),Lines!$G$3:$G$1590,0)),IF(AND(ISNUMBER($J11),$J11>0,$J11<99),INDEX(Lines!$N$3:$N$1590,MATCH(SMALL(Lines!$G$3:$G$1590,6),Lines!$G$3:$G$1590,0)),""))) | C11: =IF($J11=0,INDEX(Lines!$K$3:$K$1590,MATCH(SMALL(Lines!$G$3:$G$1590,6),Lines!$G$3:$G$1590,0)),IF(AND(ISNUMBER($J11),$J11>0,$J11<99),INDEX(Lines!$C$3:$C$1590,MATCH(SMALL(Lines!$G$3:$G$1590,6),Lines!$G$3:$G$1590,0)),"")) | D11: =IF(AND(ISNUMBER($J11),$J11>0,$J11<99),INDEX(Lines!$D$3:$D$1590,MATCH(SMALL(Lines!$G$3:$G$1590,6),Lines!$G$3:$G$1590,0)),"") | E11: =IF(AND(ISNUMBER($J11),$J11>0,$J11<99),INDEX(Lines!$E$3:$E$1590,MATCH(SMALL(Lines!$G$3:$G$1590,6),Lines!$G$3:$G$1590,0)),"") | F11: =IF(AND(ISNUMBER($J11),$J11>0,$J11<99),INDEX(Lines!$O$3:$O$1590,MATCH(SMALL(Lines!$G$3:$G$1590,6),Lines!$G$3:$G$1590,0)),"") | G11: =IF($J11=0,INDEX(Lines!$Q$3:$Q$1590,MATCH(SMALL(Lines!$G$3:$G$1590,6),Lines!$G$3:$G$1590,0)),IF(AND(ISNUMBER($J11),$J11>0,$J11<99),INDEX(Lines!$P$3:$P$1590,MATCH(SMALL(Lines!$G$3:$G$1590,6),Lines!$G$3:$G$1590,0)),"")) | H11: =IF($J11=0,INDEX(Lines!$H$3:$H$1590,MATCH(SMALL(Lines!$G$3:$G$1590,6),Lines!$G$3:$G$1590,0))&" groups",IF(AND(ISNUMBER($J11),$J11>0,$J11<99),INDEX(Lines!$I$3:$I$1590,MATCH(SMALL(Lines!$G$3:$G$1590,6),Lines!$G$3:$G$1590,0)),"")) | J11: =IFERROR(IF(MOD(SMALL(Lines!$G$3:$G$1590,6),100000)=0,-1,MOD(SMALL(Lines!$G$3:$G$1590,6),100)),"") | K11: =IF($J11=0,INDEX(Lines!$L$3:$L$1590,MATCH(SMALL(Lines!$G$3:$G$1590,6),Lines!$G$3:$G$1590,0)),"")
A12: =IF(OR($J12=0,AND(ISNUMBER($J12),$J12>0,$J12<99)),INDEX(Lines!$A$3:$A$1590,MATCH(SMALL(Lines!$G$3:$G$1590,7),Lines!$G$3:$G$1590,0)),"") | B12: =IF($J12=-1,INDEX(Lines!$J$3:$J$1590,MATCH(SMALL(Lines!$G$3:$G$1590,7),Lines!$G$3:$G$1590,0)),IF($J12=0,INDEX(Lines!$L$3:$L$1590,MATCH(SMALL(Lines!$G$3:$G$1590,7),Lines!$G$3:$G$1590,0)),IF(AND(ISNUMBER($J12),$J12>0,$J12<99),INDEX(Lines!$N$3:$N$1590,MATCH(SMALL(Lines!$G$3:$G$1590,7),Lines!$G$3:$G$1590,0)),""))) | C12: =IF($J12=0,INDEX(Lines!$K$3:$K$1590,MATCH(SMALL(Lines!$G$3:$G$1590,7),Lines!$G$3:$G$1590,0)),IF(AND(ISNUMBER($J12),$J12>0,$J12<99),INDEX(Lines!$C$3:$C$1590,MATCH(SMALL(Lines!$G$3:$G$1590,7),Lines!$G$3:$G$1590,0)),"")) | D12: =IF(AND(ISNUMBER($J12),$J12>0,$J12<99),INDEX(Lines!$D$3:$D$1590,MATCH(SMALL(Lines!$G$3:$G$1590,7),Lines!$G$3:$G$1590,0)),"") | E12: =IF(AND(ISNUMBER($J12),$J12>0,$J12<99),INDEX(Lines!$E$3:$E$1590,MATCH(SMALL(Lines!$G$3:$G$1590,7),Lines!$G$3:$G$1590,0)),"") | F12: =IF(AND(ISNUMBER($J12),$J12>0,$J12<99),INDEX(Lines!$O$3:$O$1590,MATCH(SMALL(Lines!$G$3:$G$1590,7),Lines!$G$3:$G$1590,0)),"") | G12: =IF($J12=0,INDEX(Lines!$Q$3:$Q$1590,MATCH(SMALL(Lines!$G$3:$G$1590,7),Lines!$G$3:$G$1590,0)),IF(AND(ISNUMBER($J12),$J12>0,$J12<99),INDEX(Lines!$P$3:$P$1590,MATCH(SMALL(Lines!$G$3:$G$1590,7),Lines!$G$3:$G$1590,0)),"")) | H12: =IF($J12=0,INDEX(Lines!$H$3:$H$1590,MATCH(SMALL(Lines!$G$3:$G$1590,7),Lines!$G$3:$G$1590,0))&" groups",IF(AND(ISNUMBER($J12),$J12>0,$J12<99),INDEX(Lines!$I$3:$I$1590,MATCH(SMALL(Lines!$G$3:$G$1590,7),Lines!$G$3:$G$1590,0)),"")) | J12: =IFERROR(IF(MOD(SMALL(Lines!$G$3:$G$1590,7),100000)=0,-1,MOD(SMALL(Lines!$G$3:$G$1590,7),100)),"") | K12: =IF($J12=0,INDEX(Lines!$L$3:$L$1590,MATCH(SMALL(Lines!$G$3:$G$1590,7),Lines!$G$3:$G$1590,0)),"")
A13: =IF(OR($J13=0,AND(ISNUMBER($J13),$J13>0,$J13<99)),INDEX(Lines!$A$3:$A$1590,MATCH(SMALL(Lines!$G$3:$G$1590,8),Lines!$G$3:$G$1590,0)),"") | B13: =IF($J13=-1,INDEX(Lines!$J$3:$J$1590,MATCH(SMALL(Lines!$G$3:$G$1590,8),Lines!$G$3:$G$1590,0)),IF($J13=0,INDEX(Lines!$L$3:$L$1590,MATCH(SMALL(Lines!$G$3:$G$1590,8),Lines!$G$3:$G$1590,0)),IF(AND(ISNUMBER($J13),$J13>0,$J13<99),INDEX(Lines!$N$3:$N$1590,MATCH(SMALL(Lines!$G$3:$G$1590,8),Lines!$G$3:$G$1590,0)),""))) | C13: =IF($J13=0,INDEX(Lines!$K$3:$K$1590,MATCH(SMALL(Lines!$G$3:$G$1590,8),Lines!$G$3:$G$1590,0)),IF(AND(ISNUMBER($J13),$J13>0,$J13<99),INDEX(Lines!$C$3:$C$1590,MATCH(SMALL(Lines!$G$3:$G$1590,8),Lines!$G$3:$G$1590,0)),"")) | D13: =IF(AND(ISNUMBER($J13),$J13>0,$J13<99),INDEX(Lines!$D$3:$D$1590,MATCH(SMALL(Lines!$G$3:$G$1590,8),Lines!$G$3:$G$1590,0)),"") | E13: =IF(AND(ISNUMBER($J13),$J13>0,$J13<99),INDEX(Lines!$E$3:$E$1590,MATCH(SMALL(Lines!$G$3:$G$1590,8),Lines!$G$3:$G$1590,0)),"") | F13: =IF(AND(ISNUMBER($J13),$J13>0,$J13<99),INDEX(Lines!$O$3:$O$1590,MATCH(SMALL(Lines!$G$3:$G$1590,8),Lines!$G$3:$G$1590,0)),"") | G13: =IF($J13=0,INDEX(Lines!$Q$3:$Q$1590,MATCH(SMALL(Lines!$G$3:$G$1590,8),Lines!$G$3:$G$1590,0)),IF(AND(ISNUMBER($J13),$J13>0,$J13<99),INDEX(Lines!$P$3:$P$1590,MATCH(SMALL(Lines!$G$3:$G$1590,8),Lines!$G$3:$G$1590,0)),"")) | H13: =IF($J13=0,INDEX(Lines!$H$3:$H$1590,MATCH(SMALL(Lines!$G$3:$G$1590,8),Lines!$G$3:$G$1590,0))&" groups",IF(AND(ISNUMBER($J13),$J13>0,$J13<99),INDEX(Lines!$I$3:$I$1590,MATCH(SMALL(Lines!$G$3:$G$1590,8),Lines!$G$3:$G$1590,0)),"")) | J13: =IFERROR(IF(MOD(SMALL(Lines!$G$3:$G$1590,8),100000)=0,-1,MOD(SMALL(Lines!$G$3:$G$1590,8),100)),"") | K13: =IF($J13=0,INDEX(Lines!$L$3:$L$1590,MATCH(SMALL(Lines!$G$3:$G$1590,8),Lines!$G$3:$G$1590,0)),"")
A14: =IF(OR($J14=0,AND(ISNUMBER($J14),$J14>0,$J14<99)),INDEX(Lines!$A$3:$A$1590,MATCH(SMALL(Lines!$G$3:$G$1590,9),Lines!$G$3:$G$1590,0)),"") | B14: =IF($J14=-1,INDEX(Lines!$J$3:$J$1590,MATCH(SMALL(Lines!$G$3:$G$1590,9),Lines!$G$3:$G$1590,0)),IF($J14=0,INDEX(Lines!$L$3:$L$1590,MATCH(SMALL(Lines!$G$3:$G$1590,9),Lines!$G$3:$G$1590,0)),IF(AND(ISNUMBER($J14),$J14>0,$J14<99),INDEX(Lines!$N$3:$N$1590,MATCH(SMALL(Lines!$G$3:$G$1590,9),Lines!$G$3:$G$1590,0)),""))) | C14: =IF($J14=0,INDEX(Lines!$K$3:$K$1590,MATCH(SMALL(Lines!$G$3:$G$1590,9),Lines!$G$3:$G$1590,0)),IF(AND(ISNUMBER($J14),$J14>0,$J14<99),INDEX(Lines!$C$3:$C$1590,MATCH(SMALL(Lines!$G$3:$G$1590,9),Lines!$G$3:$G$1590,0)),"")) | D14: =IF(AND(ISNUMBER($J14),$J14>0,$J14<99),INDEX(Lines!$D$3:$D$1590,MATCH(SMALL(Lines!$G$3:$G$1590,9),Lines!$G$3:$G$1590,0)),"") | E14: =IF(AND(ISNUMBER($J14),$J14>0,$J14<99),INDEX(Lines!$E$3:$E$1590,MATCH(SMALL(Lines!$G$3:$G$1590,9),Lines!$G$3:$G$1590,0)),"") | F14: =IF(AND(ISNUMBER($J14),$J14>0,$J14<99),INDEX(Lines!$O$3:$O$1590,MATCH(SMALL(Lines!$G$3:$G$1590,9),Lines!$G$3:$G$1590,0)),"") | G14: =IF($J14=0,INDEX(Lines!$Q$3:$Q$1590,MATCH(SMALL(Lines!$G$3:$G$1590,9),Lines!$G$3:$G$1590,0)),IF(AND(ISNUMBER($J14),$J14>0,$J14<99),INDEX(Lines!$P$3:$P$1590,MATCH(SMALL(Lines!$G$3:$G$1590,9),Lines!$G$3:$G$1590,0)),"")) | H14: =IF($J14=0,INDEX(Lines!$H$3:$H$1590,MATCH(SMALL(Lines!$G$3:$G$1590,9),Lines!$G$3:$G$1590,0))&" groups",IF(AND(ISNUMBER($J14),$J14>0,$J14<99),INDEX(Lines!$I$3:$I$1590,MATCH(SMALL(Lines!$G$3:$G$1590,9),Lines!$G$3:$G$1590,0)),"")) | J14: =IFERROR(IF(MOD(SMALL(Lines!$G$3:$G$1590,9),100000)=0,-1,MOD(SMALL(Lines!$G$3:$G$1590,9),100)),"") | K14: =IF($J14=0,INDEX(Lines!$L$3:$L$1590,MATCH(SMALL(Lines!$G$3:$G$1590,9),Lines!$G$3:$G$1590,0)),"")
A15: =IF(OR($J15=0,AND(ISNUMBER($J15),$J15>0,$J15<99)),INDEX(Lines!$A$3:$A$1590,MATCH(SMALL(Lines!$G$3:$G$1590,10),Lines!$G$3:$G$1590,0)),"") | B15: =IF($J15=-1,INDEX(Lines!$J$3:$J$1590,MATCH(SMALL(Lines!$G$3:$G$1590,10),Lines!$G$3:$G$1590,0)),IF($J15=0,INDEX(Lines!$L$3:$L$1590,MATCH(SMALL(Lines!$G$3:$G$1590,10),Lines!$G$3:$G$1590,0)),IF(AND(ISNUMBER($J15),$J15>0,$J15<99),INDEX(Lines!$N$3:$N$1590,MATCH(SMALL(Lines!$G$3:$G$1590,10),Lines!$G$3:$G$1590,0)),""))) | C15: =IF($J15=0,INDEX(Lines!$K$3:$K$1590,MATCH(SMALL(Lines!$G$3:$G$1590,10),Lines!$G$3:$G$1590,0)),IF(AND(ISNUMBER($J15),$J15>0,$J15<99),INDEX(Lines!$C$3:$C$1590,MATCH(SMALL(Lines!$G$3:$G$1590,10),Lines!$G$3:$G$1590,0)),"")) | D15: =IF(AND(ISNUMBER($J15),$J15>0,$J15<99),INDEX(Lines!$D$3:$D$1590,MATCH(SMALL(Lines!$G$3:$G$1590,10),Lines!$G$3:$G$1590,0)),"") | E15: =IF(AND(ISNUMBER($J15),$J15>0,$J15<99),INDEX(Lines!$E$3:$E$1590,MATCH(SMALL(Lines!$G$3:$G$1590,10),Lines!$G$3:$G$1590,0)),"") | F15: =IF(AND(ISNUMBER($J15),$J15>0,$J15<99),INDEX(Lines!$O$3:$O$1590,MATCH(SMALL(Lines!$G$3:$G$1590,10),Lines!$G$3:$G$1590,0)),"") | G15: =IF($J15=0,INDEX(Lines!$Q$3:$Q$1590,MATCH(SMALL(Lines!$G$3:$G$1590,10),Lines!$G$3:$G$1590,0)),IF(AND(ISNUMBER($J15),$J15>0,$J15<99),INDEX(Lines!$P$3:$P$1590,MATCH(SMALL(Lines!$G$3:$G$1590,10),Lines!$G$3:$G$1590,0)),"")) | H15: =IF($J15=0,INDEX(Lines!$H$3:$H$1590,MATCH(SMALL(Lines!$G$3:$G$1590,10),Lines!$G$3:$G$1590,0))&" groups",IF(AND(ISNUMBER($J15),$J15>0,$J15<99),INDEX(Lines!$I$3:$I$1590,MATCH(SMALL(Lines!$G$3:$G$1590,10),Lines!$G$3:$G$1590,0)),"")) | J15: =IFERROR(IF(MOD(SMALL(Lines!$G$3:$G$1590,10),100000)=0,-1,MOD(SMALL(Lines!$G$3:$G$1590,10),100)),"") | K15: =IF($J15=0,INDEX(Lines!$L$3:$L$1590,MATCH(SMALL(Lines!$G$3:$G$1590,10),Lines!$G$3:$G$1590,0)),"")
A16: =IF(OR($J16=0,AND(ISNUMBER($J16),$J16>0,$J16<99)),INDEX(Lines!$A$3:$A$1590,MATCH(SMALL(Lines!$G$3:$G$1590,11),Lines!$G$3:$G$1590,0)),"") | B16: =IF($J16=-1,INDEX(Lines!$J$3:$J$1590,MATCH(SMALL(Lines!$G$3:$G$1590,11),Lines!$G$3:$G$1590,0)),IF($J16=0,INDEX(Lines!$L$3:$L$1590,MATCH(SMALL(Lines!$G$3:$G$1590,11),Lines!$G$3:$G$1590,0)),IF(AND(ISNUMBER($J16),$J16>0,$J16<99),INDEX(Lines!$N$3:$N$1590,MATCH(SMALL(Lines!$G$3:$G$1590,11),Lines!$G$3:$G$1590,0)),""))) | C16: =IF($J16=0,INDEX(Lines!$K$3:$K$1590,MATCH(SMALL(Lines!$G$3:$G$1590,11),Lines!$G$3:$G$1590,0)),IF(AND(ISNUMBER($J16),$J16>0,$J16<99),INDEX(Lines!$C$3:$C$1590,MATCH(SMALL(Lines!$G$3:$G$1590,11),Lines!$G$3:$G$1590,0)),"")) | D16: =IF(AND(ISNUMBER($J16),$J16>0,$J16<99),INDEX(Lines!$D$3:$D$1590,MATCH(SMALL(Lines!$G$3:$G$1590,11),Lines!$G$3:$G$1590,0)),"") | E16: =IF(AND(ISNUMBER($J16),$J16>0,$J16<99),INDEX(Lines!$E$3:$E$1590,MATCH(SMALL(Lines!$G$3:$G$1590,11),Lines!$G$3:$G$1590,0)),"") | F16: =IF(AND(ISNUMBER($J16),$J16>0,$J16<99),INDEX(Lines!$O$3:$O$1590,MATCH(SMALL(Lines!$G$3:$G$1590,11),Lines!$G$3:$G$1590,0)),"") | G16: =IF($J16=0,INDEX(Lines!$Q$3:$Q$1590,MATCH(SMALL(Lines!$G$3:$G$1590,11),Lines!$G$3:$G$1590,0)),IF(AND(ISNUMBER($J16),$J16>0,$J16<99),INDEX(Lines!$P$3:$P$1590,MATCH(SMALL(Lines!$G$3:$G$1590,11),Lines!$G$3:$G$1590,0)),"")) | H16: =IF($J16=0,INDEX(Lines!$H$3:$H$1590,MATCH(SMALL(Lines!$G$3:$G$1590,11),Lines!$G$3:$G$1590,0))&" groups",IF(AND(ISNUMBER($J16),$J16>0,$J16<99),INDEX(Lines!$I$3:$I$1590,MATCH(SMALL(Lines!$G$3:$G$1590,11),Lines!$G$3:$G$1590,0)),"")) | J16: =IFERROR(IF(MOD(SMALL(Lines!$G$3:$G$1590,11),100000)=0,-1,MOD(SMALL(Lines!$G$3:$G$1590,11),100)),"") | K16: =IF($J16=0,INDEX(Lines!$L$3:$L$1590,MATCH(SMALL(Lines!$G$3:$G$1590,11),Lines!$G$3:$G$1590,0)),"")
A17: =IF(OR($J17=0,AND(ISNUMBER($J17),$J17>0,$J17<99)),INDEX(Lines!$A$3:$A$1590,MATCH(SMALL(Lines!$G$3:$G$1590,12),Lines!$G$3:$G$1590,0)),"") | B17: =IF($J17=-1,INDEX(Lines!$J$3:$J$1590,MATCH(SMALL(Lines!$G$3:$G$1590,12),Lines!$G$3:$G$1590,0)),IF($J17=0,INDEX(Lines!$L$3:$L$1590,MATCH(SMALL(Lines!$G$3:$G$1590,12),Lines!$G$3:$G$1590,0)),IF(AND(ISNUMBER($J17),$J17>0,$J17<99),INDEX(Lines!$N$3:$N$1590,MATCH(SMALL(Lines!$G$3:$G$1590,12),Lines!$G$3:$G$1590,0)),""))) | C17: =IF($J17=0,INDEX(Lines!$K$3:$K$1590,MATCH(SMALL(Lines!$G$3:$G$1590,12),Lines!$G$3:$G$1590,0)),IF(AND(ISNUMBER($J17),$J17>0,$J17<99),INDEX(Lines!$C$3:$C$1590,MATCH(SMALL(Lines!$G$3:$G$1590,12),Lines!$G$3:$G$1590,0)),"")) | D17: =IF(AND(ISNUMBER($J17),$J17>0,$J17<99),INDEX(Lines!$D$3:$D$1590,MATCH(SMALL(Lines!$G$3:$G$1590,12),Lines!$G$3:$G$1590,0)),"") | E17: =IF(AND(ISNUMBER($J17),$J17>0,$J17<99),INDEX(Lines!$E$3:$E$1590,MATCH(SMALL(Lines!$G$3:$G$1590,12),Lines!$G$3:$G$1590,0)),"") | F17: =IF(AND(ISNUMBER($J17),$J17>0,$J17<99),INDEX(Lines!$O$3:$O$1590,MATCH(SMALL(Lines!$G$3:$G$1590,12),Lines!$G$3:$G$1590,0)),"") | G17: =IF($J17=0,INDEX(Lines!$Q$3:$Q$1590,MATCH(SMALL(Lines!$G$3:$G$1590,12),Lines!$G$3:$G$1590,0)),IF(AND(ISNUMBER($J17),$J17>0,$J17<99),INDEX(Lines!$P$3:$P$1590,MATCH(SMALL(Lines!$G$3:$G$1590,12),Lines!$G$3:$G$1590,0)),"")) | H17: =IF($J17=0,INDEX(Lines!$H$3:$H$1590,MATCH(SMALL(Lines!$G$3:$G$1590,12),Lines!$G$3:$G$1590,0))&" groups",IF(AND(ISNUMBER($J17),$J17>0,$J17<99),INDEX(Lines!$I$3:$I$1590,MATCH(SMALL(Lines!$G$3:$G$1590,12),Lines!$G$3:$G$1590,0)),"")) | J17: =IFERROR(IF(MOD(SMALL(Lines!$G$3:$G$1590,12),100000)=0,-1,MOD(SMALL(Lines!$G$3:$G$1590,12),100)),"") | K17: =IF($J17=0,INDEX(Lines!$L$3:$L$1590,MATCH(SMALL(Lines!$G$3:$G$1590,12),Lines!$G$3:$G$1590,0)),"")
